Workbook
Name SpreadsheetBuilder_1: #REF!

Sheet NIFTY MEMBS
A1: Date | B1: NIFTY | C1: RELIANCE | D1: HDFCBANK | E1: BHARTIAIRTEL | F1: TCS | G1: ICICBANK | H1: SBI | I1: INFOSYS | J1: HUL | K1: BAJAJFIN | L1: ITC | M1: LT | N1: MARUTISUZUKI | O1: M&M | P1: KOTAKMAHINDRA | Q1: HCLTECH | R1: SUNPHARMA | S1: ULTRATECH | T1: AXISBANK | U1: BAJFINSERV | V1: TITAN | W1: NTPC | X1: ETERNAL | Y1: ADANIPORTS | Z1: ONGC | AA1: BEL | AB1: JSW STEEL | AC1: WIPRO | AD1: POWER GRID | AE1: TATA MOTORS | AF1: BAJAJ AUTO | AG1: ASIAN PAINTS | AH1: COAL INDIA | AI1: NESTLE INDIA | AJ1: TATA STEEL | AK1: JIO FINANCIAL | AL1: GRASIM INDUSTRIES | AM1: EICHERMOTORS | AN1: TRENT | AO1: SBI LIFE INSURANCE | AP1: HDFC INSURANCE | AQ1: HINDALCO INDUSTRIES | AR1: TECH MAHINDRA | AS1: CIPLA | AT1: APOLLO HOSPITAL | AU1: SHRIRAM FINANCE | AV1: TATA CONSUMER | AW1: DR REDDYS LAB | AX1: HERO MOTOCORP | AY1: INDUSIND
A2: 45658 | B2: 23742.9 | C2: 1221.25 | D2: 891.38 | E2: 1595.7 | F2: 4112.45 | G2: 1283.65 | H2: 793.2 | I2: 1882.5 | J2: 2322.1 | K2: 693.53 | L2: 457.82 | M2: 3667.5 | N2: 11208.3 | O2: 3082 | P2: 1788.4 | Q2: 1911.95 | R2: 1889.95 | S2: 11447 | T2: 1071.8 | U2: 1576.4 | V2: 3253.85 | W2: 333.65 | X2: 276.5 | Y2: 1218.7 | Z2: 236.95 | AA2: 293.9 | AB2: 905.45 | AC2: 300.3 | AD2: 310.4 | AE2: 749.25 | AF2: 8740.55 | AG2: 2304.65 | AH2: 386.4 | AI2: 1084.62 | AJ2: 136.74 | AK2: 304.45 | AL2: 2442.15 | AM2: 4885.3 | AN2: 7068.05 | AO2: 1400.4 | AP2: 617.2 | AQ2: 592.95 | AR2: 1703.85 | AS2: 1529.1 | AT2: 7369.65 | AU2: 583.73 | AV2: 920.3 | AW2: 1369 | AX2: 4184.35 | AY2: 969.4
A3: 45659 | B3: 24188.65 | C3: 1241.8 | D3: 896.88 | E3: 1609.7 | F3: 4175.75 | G3: 1290.6 | H3: 801.2 | I3: 1957.85 | J3: 2370 | K3: 738.92 | L3: 462.65 | M3: 3713.5 | N3: 11841.3 | O3: 3211.1 | P3: 1837.15 | Q3: 1972.2 | R3: 1878 | S3: 11797.7 | T3: 1086.6 | U3: 1700.65 | V3: 3388.95 | W3: 338 | X3: 284.6 | Y3: 1226 | Z3: 246.07 | AA3: 296.8 | AB3: 912.5 | AC3: 303.8 | AD3: 315.15 | AE3: 765.05 | AF3: 9079.5 | AG3: 2343.25 | AH3: 392.95 | AI3: 1100.1 | AJ3: 138.18 | AK3: 304.7 | AL3: 2543.95 | AM3: 5308.1 | AN3: 7321 | AO3: 1422.25 | AP3: 620.15 | AQ3: 599 | AR3: 1726.95 | AS3: 1537.9 | AT3: 7421.65 | AU3: 612.01 | AV3: 929.65 | AW3: 1375.05 | AX3: 4311.5 | AY3: 991.35
A4: 45660 | B4: 24004.75 | C4: 1251.15 | D4: 874.6 | E4: 1598.85 | F4: 4099.9 | G4: 1265.05 | H4: 793.4 | I4: 1938.75 | J4: 2406.25 | K4: 740.72 | L4: 455.6 | M4: 3659.9 | N4: 11934.25 | O4: 3190.55 | P4: 1838.65 | Q4: 1946.65 | R4: 1849.65 | S4: 11786 | T4: 1084.9 | U4: 1701.1 | V4: 3451.65 | W4: 339.85 | X4: 272.85 | Y4: 1199.55 | Z4: 258.89 | AA4: 291.95 | AB4: 915.05 | AC4: 294.45 | AD4: 316.05 | AE4: 790.4 | AF4: 8965.7 | AG4: 2335.95 | AH4: 393.65 | AI4: 1116.35 | AJ4: 138.36 | AK4: 307.45 | AL4: 2510 | AM4: 5310.75 | AN4: 7307.7 | AO4: 1447.7 | AP4: 623 | AQ4: 591.15 | AR4: 1689.45 | AS4: 1511.25 | AT4: 7298.35 | AU4: 609.67 | AV4: 939.45 | AW4: 1352.65 | AX4: 4243.1 | AY4: 997.9
A5: 45663 | B5: 23616.05 | C5: 1218 | D5: 855.25 | E5: 1588.45 | F5: 4095 | G5: 1264.1 | H5: 776.4 | I5: 1937.85 | J5: 2376.2 | K5: 734.93 | L5: 442.65 | M5: 3603.2 | N5: 11755.65 | O5: 3105.7 | P5: 1779.65 | Q5: 1953.05 | R5: 1847.4 | S5: 11503.6 | T5: 1063.4 | U5: 1684.6 | V5: 3470.4 | W5: 327.5 | X5: 264.85 | Y5: 1163.05 | Z5: 254.36 | AA5: 282.15 | AB5: 900.9 | AC5: 294.3 | AD5: 306 | AE5: 776.25 | AF5: 8823.85 | AG5: 2267.15 | AH5: 378.75 | AI5: 1092.5 | AJ5: 132.18 | AK5: 296.7 | AL5: 2460.55 | AM5: 5250.1 | AN5: 6998.35 | AO5: 1434.65 | AP5: 605.95 | AQ5: 574.1 | AR5: 1686.3 | AS5: 1491.4 | AT5: 7429.15 | AU5: 593.91 | AV5: 946.9 | AW5: 1350.35 | AX5: 4202.8 | AY5: 970.05
A6: 45664 | B6: 23707.9 | C6: 1240.85 | D6: 856.7 | E6: 1590.85 | F6: 4028.3 | G6: 1279.25 | H6: 778.75 | I6: 1930.85 | J6: 2390.8 | K6: 735.4 | L6: 441.1 | M6: 3643.3 | N6: 11721.3 | O6: 3108.85 | P6: 1772.05 | Q6: 1915.9 | R6: 1853.4 | S6: 11618.55 | T6: 1067.5 | U6: 1682.75 | V6: 3505.1 | W6: 328.6 | X6: 252.45 | Y6: 1174 | Z6: 263.49 | AA6: 287 | AB6: 911.8 | AC6: 294.05 | AD6: 305.05 | AE6: 793.25 | AF6: 8810.3 | AG6: 2292.6 | AH6: 379.8 | AI6: 1106.32 | AJ6: 133.38 | AK6: 299.15 | AL6: 2467.25 | AM6: 5177.3 | AN6: 6874.3 | AO6: 1477.75 | AP6: 619.85 | AQ6: 584.5 | AR6: 1671.15 | AS6: 1497.45 | AT6: 7436.75 | AU6: 591.68 | AV6: 955 | AW6: 1351.55 | AX6: 4162.05 | AY6: 983.6
A7: 45665 | B7: 23688.95 | C7: 1265.5 | D7: 847.15 | E7: 1599.2 | F7: 4108.4 | G7: 1263.75 | H7: 771.15 | I7: 1933.15 | J7: 2401 | K7: 735.54 | L7: 449.55 | M7: 3596.35 | N7: 11822 | O7: 3086.1 | P7: 1768.65 | Q7: 1932.25 | R7: 1837.75 | S7: 11403.55 | T7: 1074.95 | U7: 1697 | V7: 3484.05 | W7: 325.4 | X7: 250.05 | Y7: 1152.3 | Z7: 271.33 | AA7: 282.1 | AB7: 902.3 | AC7: 297.55 | AD7: 306.65 | AE7: 794.95 | AF7: 8642.25 | AG7: 2334.35 | AH7: 380.35 | AI7: 1109.95 | AJ7: 132.64 | AK7: 298.6 | AL7: 2435.75 | AM7: 5163.2 | AN7: 6699.1 | AO7: 1463.15 | AP7: 618 | AQ7: 586.65 | AR7: 1663.75 | AS7: 1494.9 | AT7: 7142.65 | AU7: 579.75 | AV7: 961.6 | AW7: 1370.75 | AX7: 4138.1 | AY7: 981.05
A8: 45666 | B8: 23526.5 | C8: 1254.75 | D8: 833.9 | E8: 1607.05 | F8: 4038.85 | G8: 1262.4 | H8: 760.45 | I8: 1917.3 | J8: 2435.4 | K8: 727.74 | L8: 450.1 | M8: 3527.9 | N8: 11740.55 | O8: 3126.5 | P8: 1790.2 | Q8: 1934.8 | R8: 1826.35 | S8: 11259.8 | T8: 1061.75 | U8: 1690.3 | V8: 3487.05 | W8: 320.35 | X8: 245.35 | Y8: 1132.35 | Z8: 263.18 | AA8: 281.25 | AB8: 890.95 | AC8: 292.3 | AD8: 305.25 | AE8: 780.1 | AF8: 8835.85 | AG8: 2350.2 | AH8: 372.2 | AI8: 1128.03 | AJ8: 129.93 | AK8: 289.25 | AL8: 2410.4 | AM8: 5139.9 | AN8: 6621.7 | AO8: 1468.45 | AP8: 612.2 | AQ8: 589.25 | AR8: 1642.8 | AS8: 1488.2 | AT8: 7091.55 | AU8: 561.97 | AV8: 970.1 | AW8: 1371.6 | AX8: 4141.25 | AY8: 980.9
A9: 45667 | B9: 23431.5 | C9: 1241.9 | D9: 828.38 | E9: 1615.9 | F9: 4265.65 | G9: 1249.85 | H9: 743.25 | I9: 1966.95 | J9: 2442.05 | K9: 728.8 | L9: 444.9 | M9: 3536.15 | N9: 11631.1 | O9: 3092.85 | P9: 1756.2 | Q9: 1995.1 | R9: 1784.8 | S9: 10865.2 | T9: 1040.7 | U9: 1701.25 | V9: 3440.25 | W9: 308.25 | X9: 242.95 | Y9: 1112.2 | Z9: 263.02 | AA9: 271 | AB9: 900.1 | AC9: 300.55 | AD9: 299.7 | AE9: 774.65 | AF9: 8764 | AG9: 2320.75 | AH9: 368.5 | AI9: 1123.95 | AJ9: 127.43 | AK9: 280.55 | AL9: 2364.1 | AM9: 5058.45 | AN9: 6584.1 | AO9: 1478.3 | AP9: 608.65 | AQ9: 574.45 | AR9: 1705.6 | AS9: 1468.8 | AT9: 7036.75 | AU9: 532 | AV9: 972.8 | AW9: 1354.4 | AX9: 4122.2 | AY9: 937.6
A10: 45670 | B10: 23085.95 | C10: 1239.85 | D10: 815.42 | E10: 1597.2 | F10: 4291.1 | G10: 1229.75 | H10: 729.5 | I10: 1962.2 | J10: 2451 | K10: 715.09 | L10: 439.05 | M10: 3464.3 | N10: 11497.7 | O10: 2999.65 | P10: 1738.4 | Q10: 1989.4 | R10: 1746.9 | S10: 10615.15 | T10: 1049.3 | U10: 1674.15 | V10: 3382.75 | W10: 298.2 | X10: 227.15 | Y10: 1066.65 | Z10: 255.73 | AA10: 259.6 | AB10: 883.75 | AC10: 291.85 | AD10: 287.6 | AE10: 751 | AF10: 8596.25 | AG10: 2252.65 | AH10: 362.9 | AI10: 1118.68 | AJ10: 122.93 | AK10: 266.15 | AL10: 2288.15 | AM10: 4939.1 | AN10: 6224.4 | AO10: 1467.4 | AP10: 599.75 | AQ10: 563.75 | AR10: 1659.65 | AS10: 1439.2 | AT10: 6839.6 | AU10: 521.1 | AV10: 965.45 | AW10: 1335.1 | AX10: 4043.65 | AY10: 941.7
A11: 45671 | B11: 23176.05 | C11: 1238.75 | D11: 823.3 | E11: 1600.1 | F11: 4233.05 | G11: 1240.3 | H11: 748.15 | I11: 1940.05 | J11: 2367.95 | K11: 733.5 | L11: 436.6 | M11: 3462.6 | N11: 11741.15 | O11: 3049.5 | P11: 1750.6 | Q11: 1813.55 | R11: 1770.85 | S11: 10483.75 | T11: 1051.65 | U11: 1713.5 | V11: 3322.5 | W11: 310.4 | X11: 233.6 | Y11: 1117.1 | Z11: 260.37 | AA11: 269.9 | AB11: 906.05 | AC11: 292.85 | AD11: 290.25 | AE11: 770.5 | AF11: 8611.2 | AG11: 2239.95 | AH11: 369.25 | AI11: 1109.53 | AJ11: 126.93 | AK11: 272.85 | AL11: 2310.6 | AM11: 5029.55 | AN11: 6161.15 | AO11: 1499.25 | AP11: 600.45 | AQ11: 590.9 | AR11: 1647.5 | AS11: 1447.75 | AT11: 6706.85 | AU11: 544.1 | AV11: 963.15 | AW11: 1337.55 | AX11: 4102.65 | AY11: 962.1
A12: 45672 | B12: 23213.2 | C12: 1252.2 | D12: 821.53 | E12: 1607.45 | F12: 4249.6 | G12: 1238.25 | H12: 753.7 | I12: 1949.65 | J12: 2373 | K12: 717.74 | L12: 437.35 | M12: 3501.4 | N12: 11947.4 | O12: 2960.25 | P12: 1789.6 | Q12: 1825.7 | R12: 1756.85 | S12: 10521.65 | T12: 1026.8 | U12: 1671.65 | V12: 3323.5 | W12: 321.35 | X12: 243.9 | Y12: 1128.9 | Z12: 258.18 | AA12: 267.85 | AB12: 904.05 | AC12: 292.65 | AD12: 298.65 | AE12: 763.6 | AF12: 8578 | AG12: 2229.7 | AH12: 374.6 | AI12: 1099.82 | AJ12: 126.53 | AK12: 272.4 | AL12: 2317.55 | AM12: 5081.9 | AN12: 6390.25 | AO12: 1472.75 | AP12: 594.2 | AQ12: 591.55 | AR12: 1675.95 | AS12: 1447.2 | AT12: 6691.85 | AU12: 533.2 | AV12: 955.55 | AW12: 1337.2 | AX12: 4111.9 | AY12: 962.45
A13: 45673 | B13: 23311.8 | C13: 1266.45 | D13: 826.03 | E13: 1630.2 | F13: 4206.3 | G13: 1249.1 | H13: 766.3 | I13: 1928.45 | J13: 2345 | K13: 725.97 | L13: 432.85 | M13: 3507.9 | N13: 12092.3 | O13: 2980.6 | P13: 1805.55 | Q13: 1792.25 | R13: 1763.3 | S13: 10636.2 | T13: 1038 | U13: 1697.35 | V13: 3316.9 | W13: 325.5 | X13: 241.9 | Y13: 1150.75 | Z13: 263.18 | AA13: 276.15 | AB13: 906.8 | AC13: 288.05 | AD13: 297.65 | AE13: 774.35 | AF13: 8581.95 | AG13: 2215.6 | AH13: 378.85 | AI13: 1084.65 | AJ13: 127.81 | AK13: 276.8 | AL13: 2350.7 | AM13: 5047.8 | AN13: 6211.55 | AO13: 1513.6 | AP13: 641.4 | AQ13: 602.6 | AR13: 1687.65 | AS13: 1443.5 | AT13: 6789.65 | AU13: 546.8 | AV13: 937.7 | AW13: 1302.75 | AX13: 4074.1 | AY13: 975.35
... A167: 45901 | B167: 24625.05 | C167: 1353.9 | D167: 950.6 | E167: 1900.6 | F167: 3112.6 | G167: 1411 | H167: 806.05 | I167: 1499.4 | J167: 2649.5 | K167: 889.35 | L167: 405.85 | M167: 3598.4 | N167: 14887 | O167: 3315.4 | P167: 1968.6 | Q167: 1468.4 | R167: 1563.3 | S167: 12826 | T167: 1061.5 | U167: 1943.5 | V167: 3618.6 | W167: 330.7 | X167: 321.1 | Y167: 1335.3 | Z167: 238.72 | AA167: 373.9 | AB167: 1035.5 | AC167: 250.36 | AD167: 279.85 | AE167: 690.15 | AF167: 8967 | AG167: 2570.2 | AH167: 377.9 | AI167: 1174.4 | AJ167: 156.17 | AK167: 314.05 | AL167: 2803.9 | AM167: 6280 | AN167: 5450 | AO167: 1809.8 | AP167: 781.8 | AQ167: 719.6 | AR167: 1505.5 | AS167: 1587.2 | AT167: 7671.5 | AU167: 588.6 | AV167: 1075.7 | AW167: 1279.9 | AX167: 5244 | AY167: 752.85

Sheet NIFTY_100
A1: Date | B1: Close | C1: Index_100 | E1: Rolling Peak UW | F1: Drawdown UW | I1: Rolling Peak_100 | J1: Drawdown_100 | M1: Mean | N1: SD | O1: CV% | P1: MDD
A2: 45901 | B2: 24625.05 | C2: =B2/$B$167*100 -> 103.71543 | E2: =MAX($B2:B$167) -> 25637.8 | F2: =(B2-MAX($B2:B$167))/MAX($B2:B$167) -> -0.039502219 | I2: =MAX($C2:C$167) -> 107.98091 | J2: =(C2-MAX($C2:C$167))/MAX($C2:C$167) -> -0.039502219 | L2: Unweighted | M2: =SUM(B2:B167)/166 -> 24071.595 | N2: =STDEV(B2:B167) -> 964.71747 | O2: =(N2/M2)*100 -> 4.0077007 | P2: =IFERROR(100*MIN($F$2:$F$167),"") -> -8.7065628
A3: 45898 | B3: 24426.85 | C3: =B3/$B$167*100 -> 102.88065 | E3: =MAX($B3:B$167) -> 25637.8 | F3: =(B3-MAX($B3:B$167))/MAX($B3:B$167) -> -0.047232992 | I3: =MAX($C3:C$167) -> 107.98091 | J3: =(C3-MAX($C3:C$167))/MAX($C3:C$167) -> -0.047232992 | L3: Weighted_100 | M3: =SUM(C2:C167)/166 -> 101.38439 | N3: =STDEV(C2:C167) -> 4.063183 | O3: =(N3/M3)*100 -> 4.0077007 | P3: =IFERROR(100*MIN($J$2:$J$167),"") -> -8.7065628
A4: 45897 | B4: 24500.9 | C4: =B4/$B$167*100 -> 103.19253 | E4: =MAX($B4:B$167) -> 25637.8 | F4: =(B4-MAX($B4:B$167))/MAX($B4:B$167) -> -0.044344679 | I4: =MAX($C4:C$167) -> 107.98091 | J4: =(C4-MAX($C4:C$167))/MAX($C4:C$167) -> -0.044344679
A5: 45895 | B5: 24712.05 | C5: =B5/$B$167*100 -> 104.08185 | E5: =MAX($B5:B$167) -> 25637.8 | F5: =(B5-MAX($B5:B$167))/MAX($B5:B$167) -> -0.036108792 | I5: =MAX($C5:C$167) -> 107.98091 | J5: =(C5-MAX($C5:C$167))/MAX($C5:C$167) -> -0.036108792
A6: 45894 | B6: 24967.75 | C6: =B6/$B$167*100 -> 105.15881 | E6: =MAX($B6:B$167) -> 25637.8 | F6: =(B6-MAX($B6:B$167))/MAX($B6:B$167) -> -0.026135238 | I6: =MAX($C6:C$167) -> 107.98091 | J6: =(C6-MAX($C6:C$167))/MAX($C6:C$167) -> -0.026135238 | L6: This proves that we have done our weighing of values correctly as all values in row 1 and 2 are the same
A7: 45891 | B7: 24870.1 | C7: =B7/$B$167*100 -> 104.74752 | E7: =MAX($B7:B$167) -> 25637.8 | F7: =(B7-MAX($B7:B$167))/MAX($B7:B$167) -> -0.029944067 | I7: =MAX($C7:C$167) -> 107.98091 | J7: =(C7-MAX($C7:C$167))/MAX($C7:C$167) -> -0.029944067
A8: 45890 | B8: 25083.75 | C8: =B8/$B$167*100 -> 105.64737 | E8: =MAX($B8:B$167) -> 25637.8 | F8: =(B8-MAX($B8:B$167))/MAX($B8:B$167) -> -0.021610669 | I8: =MAX($C8:C$167) -> 107.98091 | J8: =(C8-MAX($C8:C$167))/MAX($C8:C$167) -> -0.021610669
A9: 45889 | B9: 25050.55 | C9: =B9/$B$167*100 -> 105.50754 | E9: =MAX($B9:B$167) -> 25637.8 | F9: =(B9-MAX($B9:B$167))/MAX($B9:B$167) -> -0.022905632 | I9: =MAX($C9:C$167) -> 107.98091 | J9: =(C9-MAX($C9:C$167))/MAX($C9:C$167) -> -0.022905632
A10: 45888 | B10: 24980.65 | C10: =B10/$B$167*100 -> 105.21314 | E10: =MAX($B10:B$167) -> 25637.8 | F10: =(B10-MAX($B10:B$167))/MAX($B10:B$167) -> -0.025632075 | I10: =MAX($C10:C$167) -> 107.98091 | J10: =(C10-MAX($C10:C$167))/MAX($C10:C$167) -> -0.025632075
A11: 45887 | B11: 24876.95 | C11: =B11/$B$167*100 -> 104.77638 | E11: =MAX($B11:B$167) -> 25637.8 | F11: =(B11-MAX($B11:B$167))/MAX($B11:B$167) -> -0.029676883 | I11: =MAX($C11:C$167) -> 107.98091 | J11: =(C11-MAX($C11:C$167))/MAX($C11:C$167) -> -0.029676883
A12: 45883 | B12: 24631.3 | C12: =B12/$B$167*100 -> 103.74175 | E12: =MAX($B12:B$167) -> 25637.8 | F12: =(B12-MAX($B12:B$167))/MAX($B12:B$167) -> -0.039258439 | I12: =MAX($C12:C$167) -> 107.98091 | J12: =(C12-MAX($C12:C$167))/MAX($C12:C$167) -> -0.039258439
A13: 45882 | B13: 24619.35 | C13: =B13/$B$167*100 -> 103.69142 | E13: =MAX($B13:B$167) -> 25637.8 | F13: =(B13-MAX($B13:B$167))/MAX($B13:B$167) -> -0.039724547 | I13: =MAX($C13:C$167) -> 107.98091 | J13: =(C13-MAX($C13:C$167))/MAX($C13:C$167) -> -0.039724547
A14: 45881 | B14: 24487.4 | C14: =B14/$B$167*100 -> 103.13567 | E14: =MAX($B14:B$167) -> 25637.8 | F14: =(B14-MAX($B14:B$167))/MAX($B14:B$167) -> -0.044871245 | I14: =MAX($C14:C$167) -> 107.98091 | J14: =(C14-MAX($C14:C$167))/MAX($C14:C$167) -> -0.044871245
A15: 45880 | B15: 24585.05 | C15: =B15/$B$167*100 -> 103.54696 | E15: =MAX($B15:B$167) -> 25637.8 | F15: =(B15-MAX($B15:B$167))/MAX($B15:B$167) -> -0.041062416 | I15: =MAX($C15:C$167) -> 107.98091 | J15: =(C15-MAX($C15:C$167))/MAX($C15:C$167) -> -0.041062416
A16: 45877 | B16: 24363.3 | C16: =B16/$B$167*100 -> 102.61299 | E16: =MAX($B16:B$167) -> 25637.8 | F16: =(B16-MAX($B16:B$167))/MAX($B16:B$167) -> -0.049711754 | I16: =MAX($C16:C$167) -> 107.98091 | J16: =(C16-MAX($C16:C$167))/MAX($C16:C$167) -> -0.049711754
A17: 45876 | B17: 24596.15 | C17: =B17/$B$167*100 -> 103.59371 | E17: =MAX($B17:B$167) -> 25637.8 | F17: =(B17-MAX($B17:B$167))/MAX($B17:B$167) -> -0.040629461 | I17: =MAX($C17:C$167) -> 107.98091 | J17: =(C17-MAX($C17:C$167))/MAX($C17:C$167) -> -0.040629461
A18: 45875 | B18: 24574.2 | C18: =B18/$B$167*100 -> 103.50126 | E18: =MAX($B18:B$167) -> 25637.8 | F18: =(B18-MAX($B18:B$167))/MAX($B18:B$167) -> -0.041485619 | I18: =MAX($C18:C$167) -> 107.98091 | J18: =(C18-MAX($C18:C$167))/MAX($C18:C$167) -> -0.041485619
... A166: 45659 | B166: 24188.65 | C166: =B166/$B$167*100 -> 101.8774 | E166: =MAX($B166:B$167) -> 24188.65 | F166: =(B166-MAX($B166:B$167))/MAX($B166:B$167) -> 0 | I166: =MAX($C166:C$167) -> 101.8774 | J166: =(C166-MAX($C166:C$167))/MAX($C166:C$167) -> 0
A167: 45658 | B167: 23742.9 | C167: =B167/$B$167*100 -> 100 | E167: =MAX($B$167:B167) -> 23742.9 | F167: =(B167-MAX($B$167:B167))/MAX($B$167:B167) -> 0 | I167: =MAX($C$167:C167) -> 100 | J167: =(C167-MAX($C$167:C167))/MAX($C$167:C167) -> 0

Sheet EQ_25
A1: Overalll Investment Value | B1: 1000000 | C1: Equal Investment Value | E1: =B1/50 -> 20000 | F1: /company
A2: Company | B2: RELIANCE | C2: HDFCBANK | D2: BHARTIAIRTEL | E2: TCS | F2: ICICBANK | G2: SBI | H2: INFOSYS | I2: HUL | J2: BAJAJFIN | K2: ITC | L2: LT | M2: MARUTISUZUKI | N2: M&M | O2: KOTAKMAHINDRA | P2: HCLTECH | Q2: SUNPHARMA | R2: ULTRATECH | S2: AXISBANK | T2: BAJFINSERV | U2: TITAN | V2: NTPC | W2: ETERNAL | X2: ADANIPORTS | Y2: ONGC | Z2: BEL | AA2: JSW STEEL | AB2: WIPRO | AC2: POWER GRID | AD2: TATA MOTORS | AE2: BAJAJ AUTO | AF2: asian paints | AG2: COAL INDIA | AH2: NESTLE INDIA | AI2: TATA STEEL | AJ2: JIO FINANCIAL | AK2: GRASIM INDUSTRIES | AL2: EICHERMOTORS | AM2: TRENT | AN2: SBI LIFE INSURANCE | AO2: HDFC INSURANCE | AP2: HINDALCO INDUSTRIES | AQ2: TECH MAHINDRA | AR2: CIPLA | AS2: APOLLO HOSPITAL | AT2: SHRIRAM FINANCE | AU2: TATA CONSUMER | AV2: DR REDDYS LAB | AW2: HERO MOTOCORP | AX2: INDUSIND
A3: Actual Share Value on 1st Jan | B3: 1221.25 | C3: 891.38 | D3: 1595.7 | E3: 4112.45 | F3: 1283.65 | G3: 793.2 | H3: 1882.5 | I3: 2322.1 | J3: 693.53 | K3: 457.82 | L3: 3667.5 | M3: 11208.3 | N3: 3082 | O3: 1788.4 | P3: 1911.95 | Q3: 1889.95 | R3: 11447 | S3: 1071.8 | T3: 1576.4 | U3: 3253.85 | V3: 333.65 | W3: 276.5 | X3: 1218.7 | Y3: 236.95 | Z3: 293.9 | AA3: 905.45 | AB3: 300.3 | AC3: 310.4 | AD3: 749.25 | AE3: 8740.55 | AF3: 2304.65 | AG3: 386.4 | AH3: 1084.62 | AI3: 136.74 | AJ3: 304.45 | AK3: 2442.15 | AL3: 4885.3 | AM3: 7068.05 | AN3: 1400.4 | AO3: 617.2 | AP3: 592.95 | AQ3: 1703.85 | AR3: 1529.1 | AS3: 7369.65 | AT3: 583.73 | AU3: 920.3 | AV3: 1369 | AW3: 4184.35 | AX3: 969.4
A4: No of Shares basis equal investment | B4: =$E$1/B3 -> 16.376663 | C4: =$E$1/C3 -> 22.43712 | D4: =$E$1/D3 -> 12.533684 | E4: =$E$1/E3 -> 4.863281 | F4: =$E$1/F3 -> 15.580571 | G4: =$E$1/G3 -> 25.214322 | H4: =$E$1/H3 -> 10.62417 | I4: =$E$1/I3 -> 8.6128935 | ... AX4: =$E$1/AX3 -> 20.631318
A7: Mean | B7: =AVERAGE(B13:B178) -> 22020.806 | C7: =AVERAGE(C13:C178) -> 20832.22 | D7: =AVERAGE(D13:D178) -> 22477.57 | E7: =AVERAGE(E13:E178) -> 17171.774 | F7: =AVERAGE(F13:F178) -> 21227.13 | G7: =AVERAGE(G13:G178) -> 19696.228 | H7: =AVERAGE(H13:H178) -> 17343.743 | I7: =AVERAGE(I13:I178) -> 20423.422 | ... AX7: =AVERAGE(AX13:AX178) -> 17557.612 | AZ7: x
A8: Standard Deviation | B8: =STDEV(B13:B178) -> 1666.0547 | C8: =STDEV(C13:C178) -> 1441.2415 | D8: =STDEV(D13:D178) -> 1650.8459 | E8: =STDEV(E13:E178) -> 1666.6097 | F8: =STDEV(F13:F178) -> 1424.5081 | G8: =STDEV(G13:G178) -> 847.27312 | H8: =STDEV(H13:H178) -> 1668.561 | I8: =STDEV(I13:I178) -> 959.09522 | ... AX8: =STDEV(AX13:AX178) -> 2262.7875 | AZ8: x
A9: CV% | B9: =(B8/B7)*100 -> 7.5658206 | C9: =(C8/C7)*100 -> 6.9183288 | D9: =(D8/D7)*100 -> 7.3444145 | E9: =(E8/E7)*100 -> 9.7055186 | F9: =(F8/F7)*100 -> 6.7107899 | G9: =(G8/G7)*100 -> 4.3017024 | H9: =(H8/H7)*100 -> 9.6205355 | I9: =(I8/I7)*100 -> 4.6960554 | ... AX9: =(AX8/AX7)*100 -> 12.887786 | AZ9: x
A10: Correlation | B10: =CORREL(B13:B178,$AZ$13:$AZ$178) -> 0.92579132 | C10: =CORREL(C13:C178,$AZ$13:$AZ$178) -> 0.87530475 | D10: =CORREL(D13:D178,$AZ$13:$AZ$178) -> 0.86884479 | E10: =CORREL(E13:E178,$AZ$13:$AZ$178) -> -0.50561028 | F10: =CORREL(F13:F178,$AZ$13:$AZ$178) -> 0.86394719 | G10: =CORREL(G13:G178,$AZ$13:$AZ$178) -> 0.89908836 | H10: =CORREL(H13:H178,$AZ$13:$AZ$178) -> -0.39404011 | I10: =CORREL(I13:I178,$AZ$13:$AZ$178) -> 0.57675058 | ... AX10: =CORREL(AX13:AX178,$AZ$13:$AZ$178) -> -0.22251052 | AZ10: x
A12: Date | B12: RELIANCE | C12: HDFCBANK | D12: BHARTIAIRTEL | E12: TCS | F12: ICICBANK | G12: SBI | H12: INFOSYS | I12: HUL | J12: BAJAJFIN | K12: ITC | L12: LT | M12: MARUTISUZUKI | N12: M&M | O12: KOTAKMAHINDRA | P12: HCLTECH | Q12: SUNPHARMA | R12: ULTRATECH | S12: AXISBANK | T12: BAJFINSERV | U12: TITAN | V12: NTPC | W12: ETERNAL | X12: ADANIPORTS | Y12: ONGC | Z12: BEL | AA12: JSW STEEL | AB12: WIPRO | AC12: POWER GRID | AD12: TATA MOTORS | AE12: BAJAJ AUTO | AF12: ASIAN PAINTS | AG12: COAL INDIA | AH12: NESTLE INDIA | AI12: TATA STEEL | AJ12: JIO FINANCIAL | AK12: GRASIM INDUSTRIES | AL12: EICHERMOTORS | AM12: TRENT | AN12: SBI LIFE INSURANCE | AO12: HDFC INSURANCE | AP12: HINDALCO INDUSTRIES | AQ12: TECH MAHINDRA | AR12: CIPLA | AS12: APOLLO HOSPITAL | AT12: SHRIRAM FINANCE | AU12: TATA CONSUMER | AV12: DR REDDYS LAB | AW12: HERO MOTOCORP | AX12: INDUSIND | AY12: Sum | AZ12: Rebased_100
A13: 45658 | B13: =$B$4*'NIFTY MEMBS'!C2 -> 20000 | C13: =$C$4*'NIFTY MEMBS'!D2 -> 20000 | D13: =$D$4*'NIFTY MEMBS'!E2 -> 20000 | E13: =$E$4*'NIFTY MEMBS'!F2 -> 20000 | F13: =$F$4*'NIFTY MEMBS'!G2 -> 20000 | G13: =$G$4*'NIFTY MEMBS'!H2 -> 20000 | H13: =$H$4*'NIFTY MEMBS'!I2 -> 20000 | I13: =$I$4*'NIFTY MEMBS'!J2 -> 20000 | J13: =$J$4*'NIFTY MEMBS'!K2 -> 20000 | K13: =$K$4*'NIFTY MEMBS'!L2 -> 20000 | L13: =$L$4*'NIFTY MEMBS'!M2 -> 20000 | M13: =$M$4*'NIFTY MEMBS'!N2 -> 20000 | N13: =$N$4*'NIFTY MEMBS'!O2 -> 20000 | O13: =$O$4*'NIFTY MEMBS'!P2 -> 20000 | P13: =$P$4*'NIFTY MEMBS'!Q2 -> 20000 | Q13: =$Q$4*'NIFTY MEMBS'!R2 -> 20000 | R13: =$R$4*'NIFTY MEMBS'!S2 -> 20000 | S13: =$S$4*'NIFTY MEMBS'!T2 -> 20000 | T13: =$T$4*'NIFTY MEMBS'!U2 -> 20000 | U13: =$U$4*'NIFTY MEMBS'!V2 -> 20000 | V13: =$V$4*'NIFTY MEMBS'!W2 -> 20000 | W13: =$W$4*'NIFTY MEMBS'!X2 -> 20000 | X13: =$X$4*'NIFTY MEMBS'!Y2 -> 20000 | Y13: =$Y$4*'NIFTY MEMBS'!Z2 -> 20000 | Z13: =$Z$4*'NIFTY MEMBS'!AA2 -> 20000 | AA13: =$AA$4*'NIFTY MEMBS'!AB2 -> 20000 | AB13: =$AB$4*'NIFTY MEMBS'!AC2 -> 20000 | AC13: =$AC$4*'NIFTY MEMBS'!AD2 -> 20000 | AD13: =$AD$4*'NIFTY MEMBS'!AE2 -> 20000 | AE13: =$AE$4*'NIFTY MEMBS'!AF2 -> 20000 | AF13: =$AF$4*'NIFTY MEMBS'!AG2 -> 20000 | AG13: =$AG$4*'NIFTY MEMBS'!AH2 -> 20000 | AH13: =$AH$4*'NIFTY MEMBS'!AI2 -> 20000 | AI13: =$AI$4*'NIFTY MEMBS'!AJ2 -> 20000 | AJ13: =$AJ$4*'NIFTY MEMBS'!AK2 -> 20000 | AK13: =$AK$4*'NIFTY MEMBS'!AL2 -> 20000 | AL13: =$AL$4*'NIFTY MEMBS'!AM2 -> 20000 | AM13: =$AM$4*'NIFTY MEMBS'!AN2 -> 20000 | AN13: =$AN$4*'NIFTY MEMBS'!AO2 -> 20000 | AO13: =$AO$4*'NIFTY MEMBS'!AP2 -> 20000 | AP13: =$AP$4*'NIFTY MEMBS'!AQ2 -> 20000 | AQ13: =$AQ$4*'NIFTY MEMBS'!AR2 -> 20000 | AR13: =$AR$4*'NIFTY MEMBS'!AS2 -> 20000 | AS13: =$AS$4*'NIFTY MEMBS'!AT2 -> 20000 | AT13: =$AT$4*'NIFTY MEMBS'!AU2 -> 20000 | AU13: =$AU$4*'NIFTY MEMBS'!AV2 -> 20000 | AV13: =$AV$4*'NIFTY MEMBS'!AW2 -> 20000 | AW13: =$AW$4*'NIFTY MEMBS'!AX2 -> 20000 | AX13: =$AX$4*'NIFTY MEMBS'!AY2 -> 20000 | AY13: =SUM(B13:AX13) -> 980000 | AZ13: =AY13/$AY$13*100 -> 100
A14: 45659 | B14: =$B$4*'NIFTY MEMBS'!C3 -> 20336.54 | C14: =$C$4*'NIFTY MEMBS'!D3 -> 20123.404 | D14: =$D$4*'NIFTY MEMBS'!E3 -> 20175.472 | E14: =$E$4*'NIFTY MEMBS'!F3 -> 20307.846 | F14: =$F$4*'NIFTY MEMBS'!G3 -> 20108.285 | G14: =$G$4*'NIFTY MEMBS'!H3 -> 20201.715 | H14: =$H$4*'NIFTY MEMBS'!I3 -> 20800.531 | I14: =$I$4*'NIFTY MEMBS'!J3 -> 20412.558 | J14: =$J$4*'NIFTY MEMBS'!K3 -> 21308.956 | K14: =$K$4*'NIFTY MEMBS'!L3 -> 20211 | L14: =$L$4*'NIFTY MEMBS'!M3 -> 20250.852 | M14: =$M$4*'NIFTY MEMBS'!N3 -> 21129.52 | N14: =$N$4*'NIFTY MEMBS'!O3 -> 20837.768 | O14: =$O$4*'NIFTY MEMBS'!P3 -> 20545.18 | P14: =$P$4*'NIFTY MEMBS'!Q3 -> 20630.247 | Q14: =$Q$4*'NIFTY MEMBS'!R3 -> 19873.542 | R14: =$R$4*'NIFTY MEMBS'!S3 -> 20612.737 | S14: =$S$4*'NIFTY MEMBS'!T3 -> 20276.171 | T14: =$T$4*'NIFTY MEMBS'!U3 -> 21576.377 | U14: =$U$4*'NIFTY MEMBS'!V3 -> 20830.401 | V14: =$V$4*'NIFTY MEMBS'!W3 -> 20260.752 | W14: =$W$4*'NIFTY MEMBS'!X3 -> 20585.895 | X14: =$X$4*'NIFTY MEMBS'!Y3 -> 20119.8 | Y14: =$Y$4*'NIFTY MEMBS'!Z3 -> 20769.783 | Z14: =$Z$4*'NIFTY MEMBS'!AA3 -> 20197.346 | AA14: =$AA$4*'NIFTY MEMBS'!AB3 -> 20155.724 | AB14: =$AB$4*'NIFTY MEMBS'!AC3 -> 20233.1 | AC14: =$AC$4*'NIFTY MEMBS'!AD3 -> 20306.057 | AD14: =$AD$4*'NIFTY MEMBS'!AE3 -> 20421.755 | AE14: =$AE$4*'NIFTY MEMBS'!AF3 -> 20775.58 | AF14: =$AF$4*'NIFTY MEMBS'!AG3 -> 20334.975 | AG14: =$AG$4*'NIFTY MEMBS'!AH3 -> 20339.027 | AH14: =$AH$4*'NIFTY MEMBS'!AI3 -> 20285.446 | AI14: =$AI$4*'NIFTY MEMBS'!AJ3 -> 20210.619 | AJ14: =$AJ$4*'NIFTY MEMBS'!AK3 -> 20016.423 | AK14: =$AK$4*'NIFTY MEMBS'!AL3 -> 20833.692 | AL14: =$AL$4*'NIFTY MEMBS'!AM3 -> 21730.907 | AM14: =$AM$4*'NIFTY MEMBS'!AN3 -> 20715.756 | AN14: =$AN$4*'NIFTY MEMBS'!AO3 -> 20312.054 | AO14: =$AO$4*'NIFTY MEMBS'!AP3 -> 20095.593 | AP14: =$AP$4*'NIFTY MEMBS'!AQ3 -> 20204.064 | AQ14: =$AQ$4*'NIFTY MEMBS'!AR3 -> 20271.151 | AR14: =$AR$4*'NIFTY MEMBS'!AS3 -> 20115.1 | AS14: =$AS$4*'NIFTY MEMBS'!AT3 -> 20141.119 | AT14: =$AT$4*'NIFTY MEMBS'!AU3 -> 20968.941 | AU14: =$AU$4*'NIFTY MEMBS'!AV3 -> 20203.195 | AV14: =$AV$4*'NIFTY MEMBS'!AW3 -> 20088.386 | AW14: =$AW$4*'NIFTY MEMBS'!AX3 -> 20607.741 | AX14: =$AX$4*'NIFTY MEMBS'!AY3 -> 20452.857 | AY14: =SUM(B14:AX14) -> 1002301.9 | AZ14: =AY14/$AY$13*100 -> 102.27571
A15: 45660 | B15: =$B$4*'NIFTY MEMBS'!C4 -> 20489.662 | C15: =$C$4*'NIFTY MEMBS'!D4 -> 19623.505 | D15: =$D$4*'NIFTY MEMBS'!E4 -> 20039.481 | E15: =$E$4*'NIFTY MEMBS'!F4 -> 19938.966 | F15: =$F$4*'NIFTY MEMBS'!G4 -> 19710.201 | G15: =$G$4*'NIFTY MEMBS'!H4 -> 20005.043 | H15: =$H$4*'NIFTY MEMBS'!I4 -> 20597.61 | I15: =$I$4*'NIFTY MEMBS'!J4 -> 20724.775 | J15: =$J$4*'NIFTY MEMBS'!K4 -> 21360.864 | K15: =$K$4*'NIFTY MEMBS'!L4 -> 19903.019 | L15: =$L$4*'NIFTY MEMBS'!M4 -> 19958.555 | M15: =$M$4*'NIFTY MEMBS'!N4 -> 21295.379 | N15: =$N$4*'NIFTY MEMBS'!O4 -> 20704.413 | O15: =$O$4*'NIFTY MEMBS'!P4 -> 20561.955 | P15: =$P$4*'NIFTY MEMBS'!Q4 -> 20362.98 | Q15: =$Q$4*'NIFTY MEMBS'!R4 -> 19573.534 | R15: =$R$4*'NIFTY MEMBS'!S4 -> 20592.295 | S15: =$S$4*'NIFTY MEMBS'!T4 -> 20244.449 | T15: =$T$4*'NIFTY MEMBS'!U4 -> 21582.086 | U15: =$U$4*'NIFTY MEMBS'!V4 -> 21215.791 | V15: =$V$4*'NIFTY MEMBS'!W4 -> 20371.647 | W15: =$W$4*'NIFTY MEMBS'!X4 -> 19735.986 | X15: =$X$4*'NIFTY MEMBS'!Y4 -> 19685.731 | Y15: =$Y$4*'NIFTY MEMBS'!Z4 -> 21851.867 | Z15: =$Z$4*'NIFTY MEMBS'!AA4 -> 19867.302 | AA15: =$AA$4*'NIFTY MEMBS'!AB4 -> 20212.049 | AB15: =$AB$4*'NIFTY MEMBS'!AC4 -> 19610.39 | AC15: =$AC$4*'NIFTY MEMBS'!AD4 -> 20364.046 | AD15: =$AD$4*'NIFTY MEMBS'!AE4 -> 21098.432 | AE15: =$AE$4*'NIFTY MEMBS'!AF4 -> 20515.185 | AF15: =$AF$4*'NIFTY MEMBS'!AG4 -> 20271.625 | AG15: =$AG$4*'NIFTY MEMBS'!AH4 -> 20375.259 | AH15: =$AH$4*'NIFTY MEMBS'!AI4 -> 20585.09 | AI15: =$AI$4*'NIFTY MEMBS'!AJ4 -> 20236.946 | AJ15: =$AJ$4*'NIFTY MEMBS'!AK4 -> 20197.077 | AK15: =$AK$4*'NIFTY MEMBS'!AL4 -> 20555.658 | AL15: =$AL$4*'NIFTY MEMBS'!AM4 -> 21741.756 | AM15: =$AM$4*'NIFTY MEMBS'!AN4 -> 20678.122 | AN15: =$AN$4*'NIFTY MEMBS'!AO4 -> 20675.521 | AO15: =$AO$4*'NIFTY MEMBS'!AP4 -> 20187.946 | AP15: =$AP$4*'NIFTY MEMBS'!AQ4 -> 19939.287 | AQ15: =$AQ$4*'NIFTY MEMBS'!AR4 -> 19830.971 | AR15: =$AR$4*'NIFTY MEMBS'!AS4 -> 19766.529 | AS15: =$AS$4*'NIFTY MEMBS'!AT4 -> 19806.504 | AT15: =$AT$4*'NIFTY MEMBS'!AU4 -> 20888.767 | AU15: =$AU$4*'NIFTY MEMBS'!AV4 -> 20416.169 | AV15: =$AV$4*'NIFTY MEMBS'!AW4 -> 19761.14 | AW15: =$AW$4*'NIFTY MEMBS'!AX4 -> 20280.808 | AX15: =$AX$4*'NIFTY MEMBS'!AY4 -> 20587.993 | AY15: =SUM(B15:AX15) -> 998580.36 | AZ15: =AY15/$AY$13*100 -> 101.89596
A16: 45663 | B16: =$B$4*'NIFTY MEMBS'!C5 -> 19946.776 | C16: =$C$4*'NIFTY MEMBS'!D5 -> 19189.347 | D16: =$D$4*'NIFTY MEMBS'!E5 -> 19909.131 | E16: =$E$4*'NIFTY MEMBS'!F5 -> 19915.136 | F16: =$F$4*'NIFTY MEMBS'!G5 -> 19695.4 | G16: =$G$4*'NIFTY MEMBS'!H5 -> 19576.399 | H16: =$H$4*'NIFTY MEMBS'!I5 -> 20588.048 | I16: =$I$4*'NIFTY MEMBS'!J5 -> 20465.958 | J16: =$J$4*'NIFTY MEMBS'!K5 -> 21193.892 | K16: =$K$4*'NIFTY MEMBS'!L5 -> 19337.294 | L16: =$L$4*'NIFTY MEMBS'!M5 -> 19649.352 | M16: =$M$4*'NIFTY MEMBS'!N5 -> 20976.687 | N16: =$N$4*'NIFTY MEMBS'!O5 -> 20153.796 | O16: =$O$4*'NIFTY MEMBS'!P5 -> 19902.147 | P16: =$P$4*'NIFTY MEMBS'!Q5 -> 20429.928 | Q16: =$Q$4*'NIFTY MEMBS'!R5 -> 19549.724 | R16: =$R$4*'NIFTY MEMBS'!S5 -> 20098.891 | S16: =$S$4*'NIFTY MEMBS'!T5 -> 19843.254 | T16: =$T$4*'NIFTY MEMBS'!U5 -> 21372.748 | U16: =$U$4*'NIFTY MEMBS'!V5 -> 21331.039 | V16: =$V$4*'NIFTY MEMBS'!W5 -> 19631.35 | W16: =$W$4*'NIFTY MEMBS'!X5 -> 19157.324 | X16: =$X$4*'NIFTY MEMBS'!Y5 -> 19086.732 | Y16: =$Y$4*'NIFTY MEMBS'!Z5 -> 21469.508 | Z16: =$Z$4*'NIFTY MEMBS'!AA5 -> 19200.408 | AA16: =$AA$4*'NIFTY MEMBS'!AB5 -> 19899.497 | AB16: =$AB$4*'NIFTY MEMBS'!AC5 -> 19600.4 | AC16: =$AC$4*'NIFTY MEMBS'!AD5 -> 19716.495 | AD16: =$AD$4*'NIFTY MEMBS'!AE5 -> 20720.721 | AE16: =$AE$4*'NIFTY MEMBS'!AF5 -> 20190.606 | AF16: =$AF$4*'NIFTY MEMBS'!AG5 -> 19674.571 | AG16: =$AG$4*'NIFTY MEMBS'!AH5 -> 19604.037 | AH16: =$AH$4*'NIFTY MEMBS'!AI5 -> 20145.304 | AI16: =$AI$4*'NIFTY MEMBS'!AJ5 -> 19333.041 | AJ16: =$AJ$4*'NIFTY MEMBS'!AK5 -> 19490.885 | AK16: =$AK$4*'NIFTY MEMBS'!AL5 -> 20150.687 | AL16: =$AL$4*'NIFTY MEMBS'!AM5 -> 21493.46 | AM16: =$AM$4*'NIFTY MEMBS'!AN5 -> 19802.774 | AN16: =$AN$4*'NIFTY MEMBS'!AO5 -> 20489.146 | AO16: =$AO$4*'NIFTY MEMBS'!AP5 -> 19635.45 | AP16: =$AP$4*'NIFTY MEMBS'!AQ5 -> 19364.196 | AQ16: =$AQ$4*'NIFTY MEMBS'!AR5 -> 19793.996 | AR16: =$AR$4*'NIFTY MEMBS'!AS5 -> 19506.899 | AS16: =$AS$4*'NIFTY MEMBS'!AT5 -> 20161.473 | AT16: =$AT$4*'NIFTY MEMBS'!AU5 -> 20348.791 | AU16: =$AU$4*'NIFTY MEMBS'!AV5 -> 20578.072 | AV16: =$AV$4*'NIFTY MEMBS'!AW5 -> 19727.538 | AW16: =$AW$4*'NIFTY MEMBS'!AX5 -> 20088.186 | AX16: =$AX$4*'NIFTY MEMBS'!AY5 -> 20013.41 | AY16: =SUM(B16:AX16) -> 981199.91 | AZ16: =AY16/$AY$13*100 -> 100.12244
A17: 45664 | B17: =$B$4*'NIFTY MEMBS'!C6 -> 20320.983 | C17: =$C$4*'NIFTY MEMBS'!D6 -> 19221.881 | D17: =$D$4*'NIFTY MEMBS'!E6 -> 19939.212 | E17: =$E$4*'NIFTY MEMBS'!F6 -> 19590.755 | F17: =$F$4*'NIFTY MEMBS'!G6 -> 19931.445 | G17: =$G$4*'NIFTY MEMBS'!H6 -> 19635.653 | H17: =$H$4*'NIFTY MEMBS'!I6 -> 20513.679 | I17: =$I$4*'NIFTY MEMBS'!J6 -> 20591.706 | J17: =$J$4*'NIFTY MEMBS'!K6 -> 21207.446 | K17: =$K$4*'NIFTY MEMBS'!L6 -> 19269.582 | L17: =$L$4*'NIFTY MEMBS'!M6 -> 19868.03 | M17: =$M$4*'NIFTY MEMBS'!N6 -> 20915.393 | N17: =$N$4*'NIFTY MEMBS'!O6 -> 20174.238 | O17: =$O$4*'NIFTY MEMBS'!P6 -> 19817.155 | P17: =$P$4*'NIFTY MEMBS'!Q6 -> 20041.319 | Q17: =$Q$4*'NIFTY MEMBS'!R6 -> 19613.217 | R17: =$R$4*'NIFTY MEMBS'!S6 -> 20299.729 | S17: =$S$4*'NIFTY MEMBS'!T6 -> 19919.761 | T17: =$T$4*'NIFTY MEMBS'!U6 -> 21349.277 | U17: =$U$4*'NIFTY MEMBS'!V6 -> 21544.324 | V17: =$V$4*'NIFTY MEMBS'!W6 -> 19697.288 | W17: =$W$4*'NIFTY MEMBS'!X6 -> 18260.398 | X17: =$X$4*'NIFTY MEMBS'!Y6 -> 19266.431 | Y17: =$Y$4*'NIFTY MEMBS'!Z6 -> 22240.135 | Z17: =$Z$4*'NIFTY MEMBS'!AA6 -> 19530.453 | AA17: =$AA$4*'NIFTY MEMBS'!AB6 -> 20140.262 | AB17: =$AB$4*'NIFTY MEMBS'!AC6 -> 19583.75 | AC17: =$AC$4*'NIFTY MEMBS'!AD6 -> 19655.284 | AD17: =$AD$4*'NIFTY MEMBS'!AE6 -> 21174.508 | AE17: =$AE$4*'NIFTY MEMBS'!AF6 -> 20159.601 | AF17: =$AF$4*'NIFTY MEMBS'!AG6 -> 19895.429 | AG17: =$AG$4*'NIFTY MEMBS'!AH6 -> 19658.385 | AH17: =$AH$4*'NIFTY MEMBS'!AI6 -> 20400.14 | AI17: =$AI$4*'NIFTY MEMBS'!AJ6 -> 19508.556 | AJ17: =$AJ$4*'NIFTY MEMBS'!AK6 -> 19651.831 | AK17: =$AK$4*'NIFTY MEMBS'!AL6 -> 20205.557 | AL17: =$AL$4*'NIFTY MEMBS'!AM6 -> 21195.423 | AM17: =$AM$4*'NIFTY MEMBS'!AN6 -> 19451.758 | AN17: =$AN$4*'NIFTY MEMBS'!AO6 -> 21104.684 | AO17: =$AO$4*'NIFTY MEMBS'!AP6 -> 20085.872 | AP17: =$AP$4*'NIFTY MEMBS'!AQ6 -> 19714.984 | AQ17: =$AQ$4*'NIFTY MEMBS'!AR6 -> 19616.163 | AR17: =$AR$4*'NIFTY MEMBS'!AS6 -> 19586.031 | AS17: =$AS$4*'NIFTY MEMBS'!AT6 -> 20182.098 | AT17: =$AT$4*'NIFTY MEMBS'!AU6 -> 20272.386 | AU17: =$AU$4*'NIFTY MEMBS'!AV6 -> 20754.102 | AV17: =$AV$4*'NIFTY MEMBS'!AW6 -> 19745.069 | AW17: =$AW$4*'NIFTY MEMBS'!AX6 -> 19893.412 | AX17: =$AX$4*'NIFTY MEMBS'!AY6 -> 20292.965 | AY17: =SUM(B17:AX17) -> 984687.74 | AZ17: =AY17/$AY$13*100 -> 100.47834
A18: 45665 | B18: =$B$4*'NIFTY MEMBS'!C7 -> 20724.667 | C18: =$C$4*'NIFTY MEMBS'!D7 -> 19007.606 | D18: =$D$4*'NIFTY MEMBS'!E7 -> 20043.868 | E18: =$E$4*'NIFTY MEMBS'!F7 -> 19980.304 | F18: =$F$4*'NIFTY MEMBS'!G7 -> 19689.947 | G18: =$G$4*'NIFTY MEMBS'!H7 -> 19444.024 | H18: =$H$4*'NIFTY MEMBS'!I7 -> 20538.114 | I18: =$I$4*'NIFTY MEMBS'!J7 -> 20679.557 | J18: =$J$4*'NIFTY MEMBS'!K7 -> 21211.483 | K18: =$K$4*'NIFTY MEMBS'!L7 -> 19638.723 | L18: =$L$4*'NIFTY MEMBS'!M7 -> 19611.997 | M18: =$M$4*'NIFTY MEMBS'!N7 -> 21095.081 | N18: =$N$4*'NIFTY MEMBS'!O7 -> 20026.606 | O18: =$O$4*'NIFTY MEMBS'!P7 -> 19779.132 | P18: =$P$4*'NIFTY MEMBS'!Q7 -> 20212.349 | Q18: =$Q$4*'NIFTY MEMBS'!R7 -> 19447.604 | R18: =$R$4*'NIFTY MEMBS'!S7 -> 19924.085 | S18: =$S$4*'NIFTY MEMBS'!T7 -> 20058.78 | T18: =$T$4*'NIFTY MEMBS'!U7 -> 21530.069 | U18: =$U$4*'NIFTY MEMBS'!V7 -> 21414.939 | V18: =$V$4*'NIFTY MEMBS'!W7 -> 19505.47 | W18: =$W$4*'NIFTY MEMBS'!X7 -> 18086.799 | X18: =$X$4*'NIFTY MEMBS'!Y7 -> 18910.314 | Y18: =$Y$4*'NIFTY MEMBS'!Z7 -> 22901.878 | Z18: =$Z$4*'NIFTY MEMBS'!AA7 -> 19197.006 | AA18: =$AA$4*'NIFTY MEMBS'!AB7 -> 19930.421 | AB18: =$AB$4*'NIFTY MEMBS'!AC7 -> 19816.85 | AC18: =$AC$4*'NIFTY MEMBS'!AD7 -> 19758.376 | AD18: =$AD$4*'NIFTY MEMBS'!AE7 -> 21219.887 | AE18: =$AE$4*'NIFTY MEMBS'!AF7 -> 19775.071 | AF18: =$AF$4*'NIFTY MEMBS'!AG7 -> 20257.74 | AG18: =$AG$4*'NIFTY MEMBS'!AH7 -> 19686.853 | AH18: =$AH$4*'NIFTY MEMBS'!AI7 -> 20467.076 | AI18: =$AI$4*'NIFTY MEMBS'!AJ7 -> 19400.322 | AJ18: =$AJ$4*'NIFTY MEMBS'!AK7 -> 19615.7 | AK18: =$AK$4*'NIFTY MEMBS'!AL7 -> 19947.587 | AL18: =$AL$4*'NIFTY MEMBS'!AM7 -> 21137.699 | AM18: =$AM$4*'NIFTY MEMBS'!AN7 -> 18956.006 | AN18: =$AN$4*'NIFTY MEMBS'!AO7 -> 20896.173 | AO18: =$AO$4*'NIFTY MEMBS'!AP7 -> 20025.924 | AP18: =$AP$4*'NIFTY MEMBS'!AQ7 -> 19787.503 | AQ18: =$AQ$4*'NIFTY MEMBS'!AR7 -> 19529.301 | AR18: =$AR$4*'NIFTY MEMBS'!AS7 -> 19552.678 | AS18: =$AS$4*'NIFTY MEMBS'!AT7 -> 19383.96 | AT18: =$AT$4*'NIFTY MEMBS'!AU7 -> 19863.636 | AU18: =$AU$4*'NIFTY MEMBS'!AV7 -> 20897.533 | AV18: =$AV$4*'NIFTY MEMBS'!AW7 -> 20025.566 | AW18: =$AW$4*'NIFTY MEMBS'!AX7 -> 19778.938 | AX18: =$AX$4*'NIFTY MEMBS'!AY7 -> 20240.355 | AY18: =SUM(B18:AX18) -> 982611.56 | AZ18: =AY18/$AY$13*100 -> 100.26649
A19: 45666 | B19: =$B$4*'NIFTY MEMBS'!C8 -> 20548.618 | C19: =$C$4*'NIFTY MEMBS'!D8 -> 18710.314 | D19: =$D$4*'NIFTY MEMBS'!E8 -> 20142.257 | E19: =$E$4*'NIFTY MEMBS'!F8 -> 19642.063 | F19: =$F$4*'NIFTY MEMBS'!G8 -> 19668.913 | G19: =$G$4*'NIFTY MEMBS'!H8 -> 19174.231 | H19: =$H$4*'NIFTY MEMBS'!I8 -> 20369.721 | I19: =$I$4*'NIFTY MEMBS'!J8 -> 20975.841 | J19: =$J$4*'NIFTY MEMBS'!K8 -> 20986.547 | K19: =$K$4*'NIFTY MEMBS'!L8 -> 19662.75 | L19: =$L$4*'NIFTY MEMBS'!M8 -> 19238.718 | M19: =$M$4*'NIFTY MEMBS'!N8 -> 20949.743 | N19: =$N$4*'NIFTY MEMBS'!O8 -> 20288.774 | O19: =$O$4*'NIFTY MEMBS'!P8 -> 20020.13 | P19: =$P$4*'NIFTY MEMBS'!Q8 -> 20239.023 | Q19: =$Q$4*'NIFTY MEMBS'!R8 -> 19326.966 | R19: =$R$4*'NIFTY MEMBS'!S8 -> 19672.927 | S19: =$S$4*'NIFTY MEMBS'!T8 -> 19812.465 | T19: =$T$4*'NIFTY MEMBS'!U8 -> 21445.065 | U19: =$U$4*'NIFTY MEMBS'!V8 -> 21433.379 | V19: =$V$4*'NIFTY MEMBS'!W8 -> 19202.757 | W19: =$W$4*'NIFTY MEMBS'!X8 -> 17746.835 | X19: =$X$4*'NIFTY MEMBS'!Y8 -> 18582.916 | Y19: =$Y$4*'NIFTY MEMBS'!Z8 -> 22213.969 | Z19: =$Z$4*'NIFTY MEMBS'!AA8 -> 19139.163 | AA19: =$AA$4*'NIFTY MEMBS'!AB8 -> 19679.717 | AB19: =$AB$4*'NIFTY MEMBS'!AC8 -> 19467.199 | AC19: =$AC$4*'NIFTY MEMBS'!AD8 -> 19668.17 | AD19: =$AD$4*'NIFTY MEMBS'!AE8 -> 20823.49 | AE19: =$AE$4*'NIFTY MEMBS'!AF8 -> 20218.064 | AF19: =$AF$4*'NIFTY MEMBS'!AG8 -> 20395.288 | AG19: =$AG$4*'NIFTY MEMBS'!AH8 -> 19265.01 | AH19: =$AH$4*'NIFTY MEMBS'!AI8 -> 20800.465 | AI19: =$AI$4*'NIFTY MEMBS'!AJ8 -> 19003.949 | AJ19: =$AJ$4*'NIFTY MEMBS'!AK8 -> 19001.478 | AK19: =$AK$4*'NIFTY MEMBS'!AL8 -> 19739.983 | AL19: =$AL$4*'NIFTY MEMBS'!AM8 -> 21042.311 | AM19: =$AM$4*'NIFTY MEMBS'!AN8 -> 18736.993 | AN19: =$AN$4*'NIFTY MEMBS'!AO8 -> 20971.865 | AO19: =$AO$4*'NIFTY MEMBS'!AP8 -> 19837.978 | AP19: =$AP$4*'NIFTY MEMBS'!AQ8 -> 19875.2 | AQ19: =$AQ$4*'NIFTY MEMBS'!AR8 -> 19283.388 | AR19: =$AR$4*'NIFTY MEMBS'!AS8 -> 19465.045 | AS19: =$AS$4*'NIFTY MEMBS'!AT8 -> 19245.283 | AT19: =$AT$4*'NIFTY MEMBS'!AU8 -> 19254.45 | AU19: =$AU$4*'NIFTY MEMBS'!AV8 -> 21082.256 | AV19: =$AV$4*'NIFTY MEMBS'!AW8 -> 20037.984 | AW19: =$AW$4*'NIFTY MEMBS'!AX8 -> 19793.994 | AX19: =$AX$4*'NIFTY MEMBS'!AY8 -> 20237.26 | AY19: =SUM(B19:AX19) -> 976120.91 | AZ19: =AY19/$AY$13*100 -> 99.604174
A20: 45667 | B20: =$B$4*'NIFTY MEMBS'!C9 -> 20338.178 | C20: =$C$4*'NIFTY MEMBS'!D9 -> 18586.461 | D20: =$D$4*'NIFTY MEMBS'!E9 -> 20253.18 | E20: =$E$4*'NIFTY MEMBS'!F9 -> 20745.055 | F20: =$F$4*'NIFTY MEMBS'!G9 -> 19473.377 | G20: =$G$4*'NIFTY MEMBS'!H9 -> 18740.545 | H20: =$H$4*'NIFTY MEMBS'!I9 -> 20897.211 | I20: =$I$4*'NIFTY MEMBS'!J9 -> 21033.117 | J20: =$J$4*'NIFTY MEMBS'!K9 -> 21017.115 | K20: =$K$4*'NIFTY MEMBS'!L9 -> 19435.586 | L20: =$L$4*'NIFTY MEMBS'!M9 -> 19283.708 | M20: =$M$4*'NIFTY MEMBS'!N9 -> 20754.441 | N20: =$N$4*'NIFTY MEMBS'!O9 -> 20070.409 | O20: =$O$4*'NIFTY MEMBS'!P9 -> 19639.902 | P20: =$P$4*'NIFTY MEMBS'!Q9 -> 20869.793 | Q20: =$Q$4*'NIFTY MEMBS'!R9 -> 18887.272 | R20: =$R$4*'NIFTY MEMBS'!S9 -> 18983.489 | S20: =$S$4*'NIFTY MEMBS'!T9 -> 19419.668 | T20: =$T$4*'NIFTY MEMBS'!U9 -> 21583.989 | U20: =$U$4*'NIFTY MEMBS'!V9 -> 21145.72 | V20: =$V$4*'NIFTY MEMBS'!W9 -> 18477.446 | W20: =$W$4*'NIFTY MEMBS'!X9 -> 17573.237 | X20: =$X$4*'NIFTY MEMBS'!Y9 -> 18252.236 | Y20: =$Y$4*'NIFTY MEMBS'!Z9 -> 22200.464 | Z20: =$Z$4*'NIFTY MEMBS'!AA9 -> 18441.647 | AA20: =$AA$4*'NIFTY MEMBS'!AB9 -> 19881.827 | AB20: =$AB$4*'NIFTY MEMBS'!AC9 -> 20016.65 | AC20: =$AC$4*'NIFTY MEMBS'!AD9 -> 19310.567 | AD20: =$AD$4*'NIFTY MEMBS'!AE9 -> 20678.011 | AE20: =$AE$4*'NIFTY MEMBS'!AF9 -> 20053.658 | AF20: =$AF$4*'NIFTY MEMBS'!AG9 -> 20139.718 | AG20: =$AG$4*'NIFTY MEMBS'!AH9 -> 19073.499 | AH20: =$AH$4*'NIFTY MEMBS'!AI9 -> 20725.231 | AI20: =$AI$4*'NIFTY MEMBS'!AJ9 -> 18638.292 | AJ20: =$AJ$4*'NIFTY MEMBS'!AK9 -> 18429.956 | AK20: =$AK$4*'NIFTY MEMBS'!AL9 -> 19360.809 | AL20: =$AL$4*'NIFTY MEMBS'!AM9 -> 20708.861 | AM20: =$AM$4*'NIFTY MEMBS'!AN9 -> 18630.598 | AN20: =$AN$4*'NIFTY MEMBS'!AO9 -> 21112.539 | AO20: =$AO$4*'NIFTY MEMBS'!AP9 -> 19722.942 | AP20: =$AP$4*'NIFTY MEMBS'!AQ9 -> 19376.001 | AQ20: =$AQ$4*'NIFTY MEMBS'!AR9 -> 20020.542 | AR20: =$AR$4*'NIFTY MEMBS'!AS9 -> 19211.301 | AS20: =$AS$4*'NIFTY MEMBS'!AT9 -> 19096.565 | AT20: =$AT$4*'NIFTY MEMBS'!AU9 -> 18227.605 | AU20: =$AU$4*'NIFTY MEMBS'!AV9 -> 21140.932 | AV20: =$AV$4*'NIFTY MEMBS'!AW9 -> 19786.706 | AW20: =$AW$4*'NIFTY MEMBS'!AX9 -> 19702.941 | AX20: =$AX$4*'NIFTY MEMBS'!AY9 -> 19343.924 | AY20: =SUM(B20:AX20) -> 968492.92 | AZ20: =AY20/$AY$13*100 -> 98.825808
A21: 45670 | B21: =$B$4*'NIFTY MEMBS'!C10 -> 20304.606 | C21: =$C$4*'NIFTY MEMBS'!D10 -> 18295.676 | D21: =$D$4*'NIFTY MEMBS'!E10 -> 20018.801 | E21: =$E$4*'NIFTY MEMBS'!F10 -> 20868.825 | F21: =$F$4*'NIFTY MEMBS'!G10 -> 19160.207 | G21: =$G$4*'NIFTY MEMBS'!H10 -> 18393.848 | H21: =$H$4*'NIFTY MEMBS'!I10 -> 20846.746 | I21: =$I$4*'NIFTY MEMBS'!J10 -> 21110.202 | J21: =$J$4*'NIFTY MEMBS'!K10 -> 20621.747 | K21: =$K$4*'NIFTY MEMBS'!L10 -> 19180.027 | L21: =$L$4*'NIFTY MEMBS'!M10 -> 18891.888 | M21: =$M$4*'NIFTY MEMBS'!N10 -> 20516.403 | N21: =$N$4*'NIFTY MEMBS'!O10 -> 19465.607 | O21: =$O$4*'NIFTY MEMBS'!P10 -> 19440.841 | P21: =$P$4*'NIFTY MEMBS'!Q10 -> 20810.168 | Q21: =$Q$4*'NIFTY MEMBS'!R10 -> 18486.203 | R21: =$R$4*'NIFTY MEMBS'!S10 -> 18546.606 | S21: =$S$4*'NIFTY MEMBS'!T10 -> 19580.146 | T21: =$T$4*'NIFTY MEMBS'!U10 -> 21240.167 | U21: =$U$4*'NIFTY MEMBS'!V10 -> 20792.292 | V21: =$V$4*'NIFTY MEMBS'!W10 -> 17875.019 | W21: =$W$4*'NIFTY MEMBS'!X10 -> 16430.38 | X21: =$X$4*'NIFTY MEMBS'!Y10 -> 17504.718 | Y21: =$Y$4*'NIFTY MEMBS'!Z10 -> 21585.145 | Z21: =$Z$4*'NIFTY MEMBS'!AA10 -> 17665.873 | AA21: =$AA$4*'NIFTY MEMBS'!AB10 -> 19520.68 | AB21: =$AB$4*'NIFTY MEMBS'!AC10 -> 19437.229 | AC21: =$AC$4*'NIFTY MEMBS'!AD10 -> 18530.928 | AD21: =$AD$4*'NIFTY MEMBS'!AE10 -> 20046.713 | AE21: =$AE$4*'NIFTY MEMBS'!AF10 -> 19669.815 | AF21: =$AF$4*'NIFTY MEMBS'!AG10 -> 19548.738 | AG21: =$AG$4*'NIFTY MEMBS'!AH10 -> 18783.644 | AH21: =$AH$4*'NIFTY MEMBS'!AI10 -> 20628.054 | AI21: =$AI$4*'NIFTY MEMBS'!AJ10 -> 17980.108 | AJ21: =$AJ$4*'NIFTY MEMBS'!AK10 -> 17483.988 | AK21: =$AK$4*'NIFTY MEMBS'!AL10 -> 18738.816 | AL21: =$AL$4*'NIFTY MEMBS'!AM10 -> 20220.253 | AM21: =$AM$4*'NIFTY MEMBS'!AN10 -> 17612.779 | AN21: =$AN$4*'NIFTY MEMBS'!AO10 -> 20956.869 | AO21: =$AO$4*'NIFTY MEMBS'!AP10 -> 19434.543 | AP21: =$AP$4*'NIFTY MEMBS'!AQ10 -> 19015.094 | AQ21: =$AQ$4*'NIFTY MEMBS'!AR10 -> 19481.175 | AR21: =$AR$4*'NIFTY MEMBS'!AS10 -> 18824.145 | AS21: =$AS$4*'NIFTY MEMBS'!AT10 -> 18561.533 | AT21: =$AT$4*'NIFTY MEMBS'!AU10 -> 17854.145 | AU21: =$AU$4*'NIFTY MEMBS'!AV10 -> 20981.202 | AV21: =$AV$4*'NIFTY MEMBS'!AW10 -> 19504.748 | AW21: =$AW$4*'NIFTY MEMBS'!AX10 -> 19327.494 | AX21: =$AX$4*'NIFTY MEMBS'!AY10 -> 19428.512 | AY21: =SUM(B21:AX21) -> 949203.35 | AZ21: =AY21/$AY$13*100 -> 96.857484
A22: 45671 | B22: =$B$4*'NIFTY MEMBS'!C11 -> 20286.592 | C22: =$C$4*'NIFTY MEMBS'!D11 -> 18472.481 | D22: =$D$4*'NIFTY MEMBS'!E11 -> 20055.148 | E22: =$E$4*'NIFTY MEMBS'!F11 -> 20586.512 | F22: =$F$4*'NIFTY MEMBS'!G11 -> 19324.582 | G22: =$G$4*'NIFTY MEMBS'!H11 -> 18864.095 | H22: =$H$4*'NIFTY MEMBS'!I11 -> 20611.421 | I22: =$I$4*'NIFTY MEMBS'!J11 -> 20394.901 | J22: =$J$4*'NIFTY MEMBS'!K11 -> 21152.654 | K22: =$K$4*'NIFTY MEMBS'!L11 -> 19072.998 | L22: =$L$4*'NIFTY MEMBS'!M11 -> 18882.618 | M22: =$M$4*'NIFTY MEMBS'!N11 -> 20950.813 | N22: =$N$4*'NIFTY MEMBS'!O11 -> 19789.098 | O22: =$O$4*'NIFTY MEMBS'!P11 -> 19577.276 | P22: =$P$4*'NIFTY MEMBS'!Q11 -> 18970.684 | Q22: =$Q$4*'NIFTY MEMBS'!R11 -> 18739.649 | R22: =$R$4*'NIFTY MEMBS'!S11 -> 18317.026 | S22: =$S$4*'NIFTY MEMBS'!T11 -> 19623.997 | T22: =$T$4*'NIFTY MEMBS'!U11 -> 21739.406 | U22: =$U$4*'NIFTY MEMBS'!V11 -> 20421.962 | V22: =$V$4*'NIFTY MEMBS'!W11 -> 18606.324 | W22: =$W$4*'NIFTY MEMBS'!X11 -> 16896.926 | X22: =$X$4*'NIFTY MEMBS'!Y11 -> 18332.65 | Y22: =$Y$4*'NIFTY MEMBS'!Z11 -> 21976.788 | Z22: =$Z$4*'NIFTY MEMBS'!AA11 -> 18366.791 | AA22: =$AA$4*'NIFTY MEMBS'!AB11 -> 20013.253 | AB22: =$AB$4*'NIFTY MEMBS'!AC11 -> 19503.83 | AC22: =$AC$4*'NIFTY MEMBS'!AD11 -> 18701.675 | AD22: =$AD$4*'NIFTY MEMBS'!AE11 -> 20567.234 | AE22: =$AE$4*'NIFTY MEMBS'!AF11 -> 19704.023 | AF22: =$AF$4*'NIFTY MEMBS'!AG11 -> 19438.526 | AG22: =$AG$4*'NIFTY MEMBS'!AH11 -> 19112.319 | AH22: =$AH$4*'NIFTY MEMBS'!AI11 -> 20459.331 | AI22: =$AI$4*'NIFTY MEMBS'!AJ11 -> 18565.16 | AJ22: =$AJ$4*'NIFTY MEMBS'!AK11 -> 17924.125 | AK22: =$AK$4*'NIFTY MEMBS'!AL11 -> 18922.671 | AL22: =$AL$4*'NIFTY MEMBS'!AM11 -> 20590.547 | AM22: =$AM$4*'NIFTY MEMBS'!AN11 -> 17433.804 | AN22: =$AN$4*'NIFTY MEMBS'!AO11 -> 21411.74 | AO22: =$AO$4*'NIFTY MEMBS'!AP11 -> 19457.226 | AP22: =$AP$4*'NIFTY MEMBS'!AQ11 -> 19930.854 | AQ22: =$AQ$4*'NIFTY MEMBS'!AR11 -> 19338.557 | AR22: =$AR$4*'NIFTY MEMBS'!AS11 -> 18935.975 | AS22: =$AS$4*'NIFTY MEMBS'!AT11 -> 18201.271 | AT22: =$AT$4*'NIFTY MEMBS'!AU11 -> 18642.18 | AU22: =$AU$4*'NIFTY MEMBS'!AV11 -> 20931.218 | AV22: =$AV$4*'NIFTY MEMBS'!AW11 -> 19540.541 | AW22: =$AW$4*'NIFTY MEMBS'!AX11 -> 19609.497 | AX22: =$AX$4*'NIFTY MEMBS'!AY11 -> 19849.391 | AY22: =SUM(B22:AX22) -> 956798.34 | AZ22: =AY22/$AY$13*100 -> 97.632484
A23: 45672 | B23: =$B$4*'NIFTY MEMBS'!C12 -> 20506.858 | C23: =$C$4*'NIFTY MEMBS'!D12 -> 18432.767 | D23: =$D$4*'NIFTY MEMBS'!E12 -> 20147.271 | E23: =$E$4*'NIFTY MEMBS'!F12 -> 20666.999 | F23: =$F$4*'NIFTY MEMBS'!G12 -> 19292.642 | G23: =$G$4*'NIFTY MEMBS'!H12 -> 19004.034 | H23: =$H$4*'NIFTY MEMBS'!I12 -> 20713.413 | I23: =$I$4*'NIFTY MEMBS'!J12 -> 20438.396 | J23: =$J$4*'NIFTY MEMBS'!K12 -> 20698.167 | K23: =$K$4*'NIFTY MEMBS'!L12 -> 19105.762 | L23: =$L$4*'NIFTY MEMBS'!M12 -> 19094.206 | M23: =$M$4*'NIFTY MEMBS'!N12 -> 21318.844 | N23: =$N$4*'NIFTY MEMBS'!O12 -> 19209.929 | O23: =$O$4*'NIFTY MEMBS'!P12 -> 20013.42 | P23: =$P$4*'NIFTY MEMBS'!Q12 -> 19097.78 | Q23: =$Q$4*'NIFTY MEMBS'!R12 -> 18591.497 | R23: =$R$4*'NIFTY MEMBS'!S12 -> 18383.245 | S23: =$S$4*'NIFTY MEMBS'!T12 -> 19160.291 | T23: =$T$4*'NIFTY MEMBS'!U12 -> 21208.45 | U23: =$U$4*'NIFTY MEMBS'!V12 -> 20428.108 | V23: =$V$4*'NIFTY MEMBS'!W12 -> 19262.7 | W23: =$W$4*'NIFTY MEMBS'!X12 -> 17641.953 | X23: =$X$4*'NIFTY MEMBS'!Y12 -> 18526.299 | Y23: =$Y$4*'NIFTY MEMBS'!Z12 -> 21791.939 | Z23: =$Z$4*'NIFTY MEMBS'!AA12 -> 18227.288 | AA23: =$AA$4*'NIFTY MEMBS'!AB12 -> 19969.076 | AB23: =$AB$4*'NIFTY MEMBS'!AC12 -> 19490.509 | AC23: =$AC$4*'NIFTY MEMBS'!AD12 -> 19242.912 | AD23: =$AD$4*'NIFTY MEMBS'!AE12 -> 20383.05 | AE23: =$AE$4*'NIFTY MEMBS'!AF12 -> 19628.055 | AF23: =$AF$4*'NIFTY MEMBS'!AG12 -> 19349.576 | AG23: =$AG$4*'NIFTY MEMBS'!AH12 -> 19389.234 | AH23: =$AH$4*'NIFTY MEMBS'!AI12 -> 20280.282 | AI23: =$AI$4*'NIFTY MEMBS'!AJ12 -> 18506.655 | AJ23: =$AJ$4*'NIFTY MEMBS'!AK12 -> 17894.564 | AK23: =$AK$4*'NIFTY MEMBS'!AL12 -> 18979.588 | AL23: =$AL$4*'NIFTY MEMBS'!AM12 -> 20804.864 | AM23: =$AM$4*'NIFTY MEMBS'!AN12 -> 18082.074 | AN23: =$AN$4*'NIFTY MEMBS'!AO12 -> 21033.276 | AO23: =$AO$4*'NIFTY MEMBS'!AP12 -> 19254.699 | AP23: =$AP$4*'NIFTY MEMBS'!AQ12 -> 19952.778 | AQ23: =$AQ$4*'NIFTY MEMBS'!AR12 -> 19672.506 | AR23: =$AR$4*'NIFTY MEMBS'!AS12 -> 18928.782 | AS23: =$AS$4*'NIFTY MEMBS'!AT12 -> 18160.564 | AT23: =$AT$4*'NIFTY MEMBS'!AU12 -> 18268.72 | AU23: =$AU$4*'NIFTY MEMBS'!AV12 -> 20766.055 | AV23: =$AV$4*'NIFTY MEMBS'!AW12 -> 19535.427 | AW23: =$AW$4*'NIFTY MEMBS'!AX12 -> 19653.71 | AX23: =$AX$4*'NIFTY MEMBS'!AY12 -> 19856.612 | AY23: =SUM(B23:AX23) -> 958045.83 | AZ23: =AY23/$AY$13*100 -> 97.759778
A24: 45673 | B24: =$B$4*'NIFTY MEMBS'!C13 -> 20740.225 | C24: =$C$4*'NIFTY MEMBS'!D13 -> 18533.734 | D24: =$D$4*'NIFTY MEMBS'!E13 -> 20432.412 | E24: =$E$4*'NIFTY MEMBS'!F13 -> 20456.419 | F24: =$F$4*'NIFTY MEMBS'!G13 -> 19461.691 | G24: =$G$4*'NIFTY MEMBS'!H13 -> 19321.735 | H24: =$H$4*'NIFTY MEMBS'!I13 -> 20488.181 | I24: =$I$4*'NIFTY MEMBS'!J13 -> 20197.235 | J24: =$J$4*'NIFTY MEMBS'!K13 -> 20935.504 | K24: =$K$4*'NIFTY MEMBS'!L13 -> 18909.178 | L24: =$L$4*'NIFTY MEMBS'!M13 -> 19129.652 | M24: =$M$4*'NIFTY MEMBS'!N13 -> 21577.402 | N24: =$N$4*'NIFTY MEMBS'!O13 -> 19341.986 | O24: =$O$4*'NIFTY MEMBS'!P13 -> 20191.792 | P24: =$P$4*'NIFTY MEMBS'!Q13 -> 18747.875 | Q24: =$Q$4*'NIFTY MEMBS'!R13 -> 18659.753 | R24: =$R$4*'NIFTY MEMBS'!S13 -> 18583.384 | S24: =$S$4*'NIFTY MEMBS'!T13 -> 19369.285 | T24: =$T$4*'NIFTY MEMBS'!U13 -> 21534.509 | U24: =$U$4*'NIFTY MEMBS'!V13 -> 20387.541 | V24: =$V$4*'NIFTY MEMBS'!W13 -> 19511.464 | W24: =$W$4*'NIFTY MEMBS'!X13 -> 17497.288 | X24: =$X$4*'NIFTY MEMBS'!Y13 -> 18884.877 | Y24: =$Y$4*'NIFTY MEMBS'!Z13 -> 22213.969 | Z24: =$Z$4*'NIFTY MEMBS'!AA13 -> 18792.106 | AA24: =$AA$4*'NIFTY MEMBS'!AB13 -> 20029.819 | AB24: =$AB$4*'NIFTY MEMBS'!AC13 -> 19184.149 | AC24: =$AC$4*'NIFTY MEMBS'!AD13 -> 19178.479 | AD24: =$AD$4*'NIFTY MEMBS'!AE13 -> 20670.003 | AE24: =$AE$4*'NIFTY MEMBS'!AF13 -> 19637.094 | AF24: =$AF$4*'NIFTY MEMBS'!AG13 -> 19227.215 | AG24: =$AG$4*'NIFTY MEMBS'!AH13 -> 19609.213 | AH24: =$AH$4*'NIFTY MEMBS'!AI13 -> 20000.553 | AI24: =$AI$4*'NIFTY MEMBS'!AJ13 -> 18693.872 | AJ24: =$AJ$4*'NIFTY MEMBS'!AK13 -> 18183.61 | AK24: =$AK$4*'NIFTY MEMBS'!AL13 -> 19251.07 | AL24: =$AL$4*'NIFTY MEMBS'!AM13 -> 20665.261 | AM24: =$AM$4*'NIFTY MEMBS'!AN13 -> 17576.418 | AN24: =$AN$4*'NIFTY MEMBS'!AO13 -> 21616.681 | AO24: =$AO$4*'NIFTY MEMBS'!AP13 -> 20784.187 | AP24: =$AP$4*'NIFTY MEMBS'!AQ13 -> 20325.491 | AQ24: =$AQ$4*'NIFTY MEMBS'!AR13 -> 19809.842 | AR24: =$AR$4*'NIFTY MEMBS'!AS13 -> 18880.387 | AS24: =$AS$4*'NIFTY MEMBS'!AT13 -> 18425.977 | AT24: =$AT$4*'NIFTY MEMBS'!AU13 -> 18734.689 | AU24: =$AU$4*'NIFTY MEMBS'!AV13 -> 20378.138 | AV24: =$AV$4*'NIFTY MEMBS'!AW13 -> 19032.14 | AW24: =$AW$4*'NIFTY MEMBS'!AX13 -> 19473.036 | AX24: =$AX$4*'NIFTY MEMBS'!AY13 -> 20122.756 | AY24: =SUM(B24:AX24) -> 963389.28 | AZ24: =AY24/$AY$13*100 -> 98.305029
... A178: 45901 | B178: =$B$4*'NIFTY MEMBS'!C167 -> 22172.364 | C178: =$C$4*'NIFTY MEMBS'!D167 -> 21328.726 | D178: =$D$4*'NIFTY MEMBS'!E167 -> 23821.52 | E178: =$E$4*'NIFTY MEMBS'!F167 -> 15137.448 | F178: =$F$4*'NIFTY MEMBS'!G167 -> 21984.186 | G178: =$G$4*'NIFTY MEMBS'!H167 -> 20324.004 | H178: =$H$4*'NIFTY MEMBS'!I167 -> 15929.88 | I178: =$I$4*'NIFTY MEMBS'!J167 -> 22819.861 | J178: =$J$4*'NIFTY MEMBS'!K167 -> 25647.052 | K178: =$K$4*'NIFTY MEMBS'!L167 -> 17729.675 | L178: =$L$4*'NIFTY MEMBS'!M167 -> 19623.177 | M178: =$M$4*'NIFTY MEMBS'!N167 -> 26564.243 | N178: =$N$4*'NIFTY MEMBS'!O167 -> 21514.601 | O178: =$O$4*'NIFTY MEMBS'!P167 -> 22015.209 | P178: =$P$4*'NIFTY MEMBS'!Q167 -> 15360.234 | Q178: =$Q$4*'NIFTY MEMBS'!R167 -> 16543.295 | R178: =$R$4*'NIFTY MEMBS'!S167 -> 22409.365 | S178: =$S$4*'NIFTY MEMBS'!T167 -> 19807.8 | T178: =$T$4*'NIFTY MEMBS'!U167 -> 24657.447 | U178: =$U$4*'NIFTY MEMBS'!V167 -> 22241.96 | V178: =$V$4*'NIFTY MEMBS'!W167 -> 19823.168 | W178: =$W$4*'NIFTY MEMBS'!X167 -> 23226.04 | X178: =$X$4*'NIFTY MEMBS'!Y167 -> 21913.514 | Y178: =$Y$4*'NIFTY MEMBS'!Z167 -> 20149.399 | Z178: =$Z$4*'NIFTY MEMBS'!AA167 -> 25444.029 | AA178: =$AA$4*'NIFTY MEMBS'!AB167 -> 22872.605 | AB178: =$AB$4*'NIFTY MEMBS'!AC167 -> 16673.993 | AC178: =$AC$4*'NIFTY MEMBS'!AD167 -> 18031.572 | AD178: =$AD$4*'NIFTY MEMBS'!AE167 -> 18422.422 | AE178: =$AE$4*'NIFTY MEMBS'!AF167 -> 20518.16 | AF178: =$AF$4*'NIFTY MEMBS'!AG167 -> 22304.471 | AG178: =$AG$4*'NIFTY MEMBS'!AH167 -> 19560.041 | AH178: =$AH$4*'NIFTY MEMBS'!AI167 -> 21655.511 | AI178: =$AI$4*'NIFTY MEMBS'!AJ167 -> 22841.89 | AJ178: =$AJ$4*'NIFTY MEMBS'!AK167 -> 20630.645 | AK178: =$AK$4*'NIFTY MEMBS'!AL167 -> 22962.553 | AL178: =$AL$4*'NIFTY MEMBS'!AM167 -> 25709.782 | AM178: =$AM$4*'NIFTY MEMBS'!AN167 -> 15421.509 | AN178: =$AN$4*'NIFTY MEMBS'!AO167 -> 25846.901 | AO178: =$AO$4*'NIFTY MEMBS'!AP167 -> 25333.765 | AP178: =$AP$4*'NIFTY MEMBS'!AQ167 -> 24271.861 | AQ178: =$AQ$4*'NIFTY MEMBS'!AR167 -> 17671.743 | AR178: =$AR$4*'NIFTY MEMBS'!AS167 -> 20759.924 | AS178: =$AS$4*'NIFTY MEMBS'!AT167 -> 20819.171 | AT178: =$AT$4*'NIFTY MEMBS'!AU167 -> 20166.858 | AU178: =$AU$4*'NIFTY MEMBS'!AV167 -> 23377.16 | AV178: =$AV$4*'NIFTY MEMBS'!AW167 -> 18698.32 | AW178: =$AW$4*'NIFTY MEMBS'!AX167 -> 25064.825 | AX178: =$AX$4*'NIFTY MEMBS'!AY167 -> 15532.288 | AY178: =SUM(B178:AX178) -> 1033336.2 | AZ178: =AY178/$AY$13*100 -> 105.44247
AZ180: x
AZ181: x

Sheet NIFTY_100 vs EQ_25 STATS
A1: Date | B1: NIFTY_100 | C1: EQ_25 | E1: Rolling Peak_NIFTY | F1: Drawdown_NIFTY | H1: Rolling Peak_EQ | I1: Drawdown_EQ | L1: Mean | M1: SD | N1: CV% | O1: MDD
A2: 45658 | B2: 100 | C2: 100 | E2: =MAX($B$2:B2) -> 100 | F2: =B2/E2-1 -> 0 | H2: =MAX($C$2:C2) -> 100 | I2: =C2/H2-1 -> 0 | K2: NIFTY_100 | L2: =AVERAGE(B2:B167) -> 101.38439 | M2: =STDEV(B2:B167) -> 4.063183 | N2: =(M2/L2)*100 -> 4.0077007 | O2: =MIN(F2:F167) -> -0.087065628
A3: 45659 | B3: 101.8774 | C3: 102.27571 | E3: =MAX($B$2:B3) -> 101.8774 | F3: =B3/E3-1 -> 0 | H3: =MAX($C$2:C3) -> 102.27571 | I3: =C3/H3-1 -> 0 | K3: EQ_25 | L3: =AVERAGE(B3:B168) -> 101.39278 | M3: =STDEV(C2:C167) -> 3.9430157 | N3: =(M3/L3)*100 -> 3.8888525 | O3: =MIN(I2:I167) -> -0.091054804
A4: 45660 | B4: 101.10286 | C4: 101.89596 | E4: =MAX($B$2:B4) -> 101.8774 | F4: =B4/E4-1 -> -0.0076027393 | H4: =MAX($C$2:C4) -> 102.27571 | I4: =C4/H4-1 -> -0.0037130283
A5: 45663 | B5: 99.465735 | C5: 100.12244 | E5: =MAX($B$2:B5) -> 101.8774 | F5: =B5/E5-1 -> -0.02367226 | H5: =MAX($C$2:C5) -> 102.27571 | I5: =C5/H5-1 -> -0.021053567 | N5: Correlation | O5: =CORREL(B2:B167,C2:C167) -> 0.99141112
A6: 45664 | B6: 99.852588 | C6: 100.47834 | E6: =MAX($B$2:B6) -> 101.8774 | F6: =B6/E6-1 -> -0.019875024 | H6: =MAX($C$2:C6) -> 102.27571 | I6: =C6/H6-1 -> -0.017573743
A7: 45665 | B7: 99.772774 | C7: 100.26649 | E7: =MAX($B$2:B7) -> 101.8774 | F7: =B7/E7-1 -> -0.020658449 | H7: =MAX($C$2:C7) -> 102.27571 | I7: =C7/H7-1 -> -0.019645156
A8: 45666 | B8: 99.08857 | C8: 99.604174 | E8: =MAX($B$2:B8) -> 101.8774 | F8: =B8/E8-1 -> -0.027374409 | H8: =MAX($C$2:C8) -> 102.27571 | I8: =C8/H8-1 -> -0.026120902
A9: 45667 | B9: 98.68845 | C9: 98.825808 | E9: =MAX($B$2:B9) -> 101.8774 | F9: =B9/E9-1 -> -0.031301871 | H9: =MAX($C$2:C9) -> 102.27571 | I9: =C9/H9-1 -> -0.033731369
A10: 45670 | B10: 97.233068 | C10: 96.857484 | E10: =MAX($B$2:B10) -> 101.8774 | F10: =B10/E10-1 -> -0.045587497 | H10: =MAX($C$2:C10) -> 102.27571 | I10: =C10/H10-1 -> -0.052976641 | K10: Monthly Data Chart
A11: 45671 | B11: 97.612549 | C11: 97.632484 | E11: =MAX($B$2:B11) -> 101.8774 | F11: =B11/E11-1 -> -0.041862609 | H11: =MAX($C$2:C11) -> 102.27571 | I11: =C11/H11-1 -> -0.045399088 | L11: NIFTY_100 | M11: EQ_25
A12: 45672 | B12: 97.769017 | C12: 97.759778 | E12: =MAX($B$2:B12) -> 101.8774 | F12: =B12/E12-1 -> -0.040326765 | H12: =MAX($C$2:C12) -> 102.27571 | I12: =C12/H12-1 -> -0.044154469 | K12: 45658 | L12: 100 | M12: 100
A13: 45673 | B13: 98.184299 | C13: 98.305029 | E13: =MAX($B$2:B13) -> 101.8774 | F13: =B13/E13-1 -> -0.036250473 | H13: =MAX($C$2:C13) -> 102.27571 | I13: =C13/H13-1 -> -0.038823288 | K13: 45689 | L13: 98.901777 | M13: 99.419372
A14: 45674 | B14: 97.726899 | C14: 98.421702 | E14: =MAX($B$2:B14) -> 101.8774 | F14: =B14/E14-1 -> -0.040740182 | H14: =MAX($C$2:C14) -> 102.27571 | I14: =C14/H14-1 -> -0.037682515 | K14: 45719 | L14: 93.161745 | M14: 93.31629
A15: 45677 | B15: 98.323078 | C15: 98.843091 | E15: =MAX($B$2:B15) -> 101.8774 | F15: =B15/E15-1 -> -0.034888264 | H15: =MAX($C$2:C15) -> 102.27571 | I15: =C15/H15-1 -> -0.033562389 | K15: 45748 | L15: 97.568957 | M15: 97.619194
A16: 45678 | B16: 96.974885 | C16: 97.374383 | E16: =MAX($B$2:B16) -> 101.8774 | F16: =B16/E16-1 -> -0.048121743 | H16: =MAX($C$2:C16) -> 102.27571 | I16: =C16/H16-1 -> -0.047922671 | K16: 45779 | L16: 102.54308 | M16: 101.24745
A17: 45679 | B17: 97.525365 | C17: 97.649028 | E17: =MAX($B$2:B17) -> 101.8774 | F17: =B17/E17-1 -> -0.042718382 | H17: =MAX($C$2:C17) -> 102.27571 | I17: =C17/H17-1 -> -0.045237327 | K17: 45810 | L17: 104.10102 | M17: 103.51874
A18: 45680 | B18: 97.735955 | C18: 98.210166 | E18: =MAX($B$2:B18) -> 101.8774 | F18: =B18/E18-1 -> -0.040651297 | H18: =MAX($C$2:C18) -> 102.27571 | I18: =C18/H18-1 -> -0.039750805 | K18: 45839 | L18: 107.57658 | M18: 107.32735
A19: 45681 | B19: 97.259391 | C19: 97.523569 | E19: =MAX($B$2:B19) -> 101.8774 | F19: =B19/E19-1 -> -0.045329111 | H19: =MAX($C$2:C19) -> 102.27571 | I19: =C19/H19-1 -> -0.046464002 | K19: 45870 | L19: 103.46398 | M19: 102.6319
A20: 45684 | B20: 96.151481 | C20: 95.966688 | E20: =MAX($B$2:B20) -> 101.8774 | F20: =B20/E20-1 -> -0.056204046 | H20: =MAX($C$2:C20) -> 102.27571 | I20: =C20/H20-1 -> -0.061686391 | K20: 45901 | L20: 103.71543 | M20: 105.44247
A21: 45685 | B21: 96.691011 | C21: 96.121721 | E21: =MAX($B$2:B21) -> 101.8774 | F21: =B21/E21-1 -> -0.050908174 | H21: =MAX($C$2:C21) -> 102.27571 | I21: =C21/H21-1 -> -0.060170557
A22: 45686 | B22: 97.558007 | C22: 97.538931 | E22: =MAX($B$2:B22) -> 101.8774 | F22: =B22/E22-1 -> -0.042397984 | H22: =MAX($C$2:C22) -> 102.27571 | I22: =C22/H22-1 -> -0.046313798
A23: 45687 | B23: 97.921905 | C23: 97.852005 | E23: =MAX($B$2:B23) -> 101.8774 | F23: =B23/E23-1 -> -0.038826061 | H23: =MAX($C$2:C23) -> 102.27571 | I23: =C23/H23-1 -> -0.043252725
A24: 45688 | B24: 99.012336 | C24: 99.373964 | E24: =MAX($B$2:B24) -> 101.8774 | F24: =B24/E24-1 -> -0.028122694 | H24: =MAX($C$2:C24) -> 102.27571 | I24: =C24/H24-1 -> -0.028371775
A25: 45689 | B25: 98.901777 | C25: 99.419372 | E25: =MAX($B$2:B25) -> 101.8774 | F25: =B25/E25-1 -> -0.029207914 | H25: =MAX($C$2:C25) -> 102.27571 | I25: =C25/H25-1 -> -0.027927801
A26: 45691 | B26: 98.39173 | C26: 98.94173 | E26: =MAX($B$2:B26) -> 101.8774 | F26: =B26/E26-1 -> -0.034214394 | H26: =MAX($C$2:C26) -> 102.27571 | I26: =C26/H26-1 -> -0.032597944
A27: 45692 | B27: 99.984627 | C27: 100.1995 | E27: =MAX($B$2:B27) -> 101.8774 | F27: =B27/E27-1 -> -0.018578962 | H27: =MAX($C$2:C27) -> 102.27571 | I27: =C27/H27-1 -> -0.020300144
A28: 45693 | B28: 99.803731 | C28: 100.10187 | E28: =MAX($B$2:B28) -> 101.8774 | F28: =B28/E28-1 -> -0.020354588 | H28: =MAX($C$2:C28) -> 102.27571 | I28: =C28/H28-1 -> -0.021254644
A29: 45694 | B29: 99.412245 | C29: 99.506662 | E29: =MAX($B$2:B29) -> 101.8774 | F29: =B29/E29-1 -> -0.024197299 | H29: =MAX($C$2:C29) -> 102.27571 | I29: =C29/H29-1 -> -0.027074327
A30: 45695 | B30: 99.229454 | C30: 99.72801 | E30: =MAX($B$2:B30) -> 101.8774 | F30: =B30/E30-1 -> -0.025991529 | H30: =MAX($C$2:C30) -> 102.27571 | I30: =C30/H30-1 -> -0.024910093
A31: 45698 | B31: 98.478282 | C31: 98.71413 | E31: =MAX($B$2:B31) -> 101.8774 | F31: =B31/E31-1 -> -0.033364822 | H31: =MAX($C$2:C31) -> 102.27571 | I31: =C31/H31-1 -> -0.034823303
A32: 45699 | B32: 97.173471 | C32: 96.934759 | E32: =MAX($B$2:B32) -> 101.8774 | F32: =B32/E32-1 -> -0.046172482 | H32: =MAX($C$2:C32) -> 102.27571 | I32: =C32/H32-1 -> -0.052221087
... A167: 45901 | B167: 103.71543 | C167: 105.44247 | E167: =MAX($B$2:B167) -> 107.98091 | F167: =B167/E167-1 -> -0.039502219 | H167: =MAX($C$2:C167) -> 107.52617 | I167: =C167/H167-1 -> -0.019378547

Sheet Stock of Choice_ BAJAJFIN
A1: Date | B1: BAJAJFIN | C1: Based to 100 | E1: Rolling Peak | F1: Drawdown | H1: Mean | I1: SD | J1: CV% | K1: MDD
A2: 45658 | B2: 693.53 | C2: =B2/$B$2*100 -> 100 | E2: =MAX($C$2:C2) -> 100 | F2: =C2/E2-1 -> 0 | H2: =AVERAGE(C2:C167) -> 125.67806 | I2: =STDEV(C2:C167) -> 9.1508366 | J2: =(I2/H2)*100 -> 7.2811726 | K2: =MIN(F2:F167) -> -0.11907467
A3: 45659 | B3: 738.92 | C3: =B3/$B$2*100 -> 106.54478 | E3: =MAX($C$2:C3) -> 106.54478 | F3: =C3/E3-1 -> 0
A4: 45660 | B4: 740.72 | C4: =B4/$B$2*100 -> 106.80432 | E4: =MAX($C$2:C4) -> 106.80432 | F4: =C4/E4-1 -> 0
A5: 45663 | B5: 734.93 | C5: =B5/$B$2*100 -> 105.96946 | E5: =MAX($C$2:C5) -> 106.80432 | F5: =C5/E5-1 -> -0.0078167189
A6: 45664 | B6: 735.4 | C6: =B6/$B$2*100 -> 106.03723 | E6: =MAX($C$2:C6) -> 106.80432 | F6: =C6/E6-1 -> -0.0071822011
A7: 45665 | B7: 735.54 | C7: =B7/$B$2*100 -> 106.05742 | E7: =MAX($C$2:C7) -> 106.80432 | F7: =C7/E7-1 -> -0.0069931958
A8: 45666 | B8: 727.74 | C8: =B8/$B$2*100 -> 104.93274 | E8: =MAX($C$2:C8) -> 106.80432 | F8: =C8/E8-1 -> -0.017523491
A9: 45667 | B9: 728.8 | C9: =B9/$B$2*100 -> 105.08558 | E9: =MAX($C$2:C9) -> 106.80432 | F9: =C9/E9-1 -> -0.016092451
A10: 45670 | B10: 715.09 | C10: =B10/$B$2*100 -> 103.10873 | E10: =MAX($C$2:C10) -> 106.80432 | F10: =C10/E10-1 -> -0.034601469
A11: 45671 | B11: 733.5 | C11: =B11/$B$2*100 -> 105.76327 | E11: =MAX($C$2:C11) -> 106.80432 | F11: =C11/E11-1 -> -0.0097472729
A12: 45672 | B12: 717.74 | C12: =B12/$B$2*100 -> 103.49084 | E12: =MAX($C$2:C12) -> 106.80432 | F12: =C12/E12-1 -> -0.031023869
A13: 45673 | B13: 725.97 | C13: =B13/$B$2*100 -> 104.67752 | E13: =MAX($C$2:C13) -> 106.80432 | F13: =C13/E13-1 -> -0.019913058
A14: 45674 | B14: 718.21 | C14: =B14/$B$2*100 -> 103.55861 | E14: =MAX($C$2:C14) -> 106.80432 | F14: =C14/E14-1 -> -0.030389351
... A167: 45901 | B167: 889.35 | C167: =B167/$B$2*100 -> 128.23526 | E167: =MAX($C$2:C167) -> 139.61905 | F167: =C167/E167-1 -> -0.081534648

Sheet EQ_25vsBAJAJFIN
A1: Date | B1: EQ_25 | C1: BAJAJFIN
A2: 45658 | B2: 100 | C2: 100
A3: 45659 | B3: 102.27571 | C3: 106.54478
A4: 45660 | B4: 101.89596 | C4: 106.80432
A5: 45663 | B5: 100.12244 | C5: 105.96946
A6: 45664 | B6: 100.47834 | C6: 106.03723
A7: 45665 | B7: 100.26649 | C7: 106.05742
A8: 45666 | B8: 99.604174 | C8: 104.93274
A9: 45667 | B9: 98.825808 | C9: 105.08558
A10: 45670 | B10: 96.857484 | C10: 103.10873
A11: 45671 | B11: 97.632484 | C11: 105.76327
A12: 45672 | B12: 97.759778 | C12: 103.49084
A13: 45673 | B13: 98.305029 | C13: 104.67752
... A16: 45678 | B16: 97.374383 | C16: 105.13749
A17: 45679 | B17: 97.649028 | C17: 106.66013 | F17: Image 6. EQ_25 vs BAJAJFIN day to day performance
A18: 45680 | B18: 98.210166 | C18: 107.32485
A19: 45681 | B19: 97.523569 | C19: 107.25708
A20: 45684 | B20: 95.966688 | C20: 105.19228
A21: 45685 | B21: 96.121721 | C21: 109.67947
A22: 45686 | B22: 97.538931 | C22: 111.88701
A23: 45687 | B23: 97.852005 | C23: 113.93307
A24: 45688 | B24: 99.373964 | C24: 113.69515
A25: 45689 | B25: 99.419372 | C25: 115.35334
A26: 45691 | B26: 98.94173 | C26: 121.4915
A27: 45692 | B27: 100.1995 | C27: 122.20524
A28: 45693 | B28: 100.10187 | C28: 122.69837
A29: 45694 | B29: 99.506662 | C29: 122.66665
... A167: 45901 | B167: 105.44247 | C167: 128.23526

Sheet EQ_25 (2)
A1: Overalll Investment Value | B1: 1000000 | C1: Equal Investment Value | E1: =B1/50 -> 20000 | F1: /company
